[2023-05-01T13:00:55.019+0000] {taskinstance.py:1090} INFO - Dependencies all met for dep_context=non-requeueable deps ti=<TaskInstance: push_to_bigquery.push_csv_to_cloud_storage scheduled__2023-05-01T11:30:00+00:00 [queued]>
[2023-05-01T13:00:55.036+0000] {taskinstance.py:1090} INFO - Dependencies all met for dep_context=requeueable deps ti=<TaskInstance: push_to_bigquery.push_csv_to_cloud_storage scheduled__2023-05-01T11:30:00+00:00 [queued]>
[2023-05-01T13:00:55.042+0000] {taskinstance.py:1288} INFO - 
--------------------------------------------------------------------------------
[2023-05-01T13:00:55.044+0000] {taskinstance.py:1289} INFO - Starting attempt 1 of 1
[2023-05-01T13:00:55.045+0000] {taskinstance.py:1290} INFO - 
--------------------------------------------------------------------------------
[2023-05-01T13:00:55.073+0000] {taskinstance.py:1309} INFO - Executing <Task(PythonOperator): push_csv_to_cloud_storage> on 2023-05-01 11:30:00+00:00
[2023-05-01T13:00:55.084+0000] {standard_task_runner.py:55} INFO - Started process 5807 to run task
[2023-05-01T13:00:55.098+0000] {standard_task_runner.py:82} INFO - Running: ['***', 'tasks', 'run', 'push_to_bigquery', 'push_csv_to_cloud_storage', 'scheduled__2023-05-01T11:30:00+00:00', '--job-id', '2045', '--raw', '--subdir', 'DAGS_FOLDER/push_to_bigquery_dag.py', '--cfg-path', '/tmp/tmpq_qc9gwb']
[2023-05-01T13:00:55.115+0000] {standard_task_runner.py:83} INFO - Job 2045: Subtask push_csv_to_cloud_storage
[2023-05-01T13:00:55.242+0000] {task_command.py:389} INFO - Running <TaskInstance: push_to_bigquery.push_csv_to_cloud_storage scheduled__2023-05-01T11:30:00+00:00 [running]> on host 5d4cd8acb346
[2023-05-01T13:00:55.523+0000] {warnings.py:110} WARNING - /home/***/.local/lib/python3.7/site-packages/***/utils/context.py:205: AirflowContextDeprecationWarning: Accessing 'execution_date' from the template is deprecated and will be removed in a future version. Please use 'data_interval_start' or 'logical_date' instead.
  warnings.warn(_create_deprecation_warning(key, self._deprecation_replacements[key]))

[2023-05-01T13:00:55.622+0000] {taskinstance.py:1518} INFO - Exporting the following env vars:
AIRFLOW_CTX_DAG_OWNER=***
AIRFLOW_CTX_DAG_ID=push_to_bigquery
AIRFLOW_CTX_TASK_ID=push_csv_to_cloud_storage
AIRFLOW_CTX_EXECUTION_DATE=2023-05-01T11:30:00+00:00
AIRFLOW_CTX_TRY_NUMBER=1
AIRFLOW_CTX_DAG_RUN_ID=scheduled__2023-05-01T11:30:00+00:00
[2023-05-01T13:00:55.700+0000] {connectionpool.py:813} WARNING - Retrying (Retry(total=2, connect=None, read=None, redirect=None, status=None)) after connection broken by 'NewConnectionError('<urllib3.connection.HTTPSConnection object at 0xffff9bfc6d50>: Failed to establish a new connection: [Errno -2] Name or service not known')': /token
[2023-05-01T13:00:55.705+0000] {connectionpool.py:813} WARNING - Retrying (Retry(total=1, connect=None, read=None, redirect=None, status=None)) after connection broken by 'NewConnectionError('<urllib3.connection.HTTPSConnection object at 0xffff9bffc2d0>: Failed to establish a new connection: [Errno -2] Name or service not known')': /token
[2023-05-01T13:00:55.712+0000] {connectionpool.py:813} WARNING - Retrying (Retry(total=0, connect=None, read=None, redirect=None, status=None)) after connection broken by 'NewConnectionError('<urllib3.connection.HTTPSConnection object at 0xffff9bffc650>: Failed to establish a new connection: [Errno -2] Name or service not known')': /token
[2023-05-01T13:00:56.855+0000] {connectionpool.py:813} WARNING - Retrying (Retry(total=2, connect=None, read=None, redirect=None, status=None)) after connection broken by 'NewConnectionError('<urllib3.connection.HTTPSConnection object at 0xffff9bffce50>: Failed to establish a new connection: [Errno -2] Name or service not known')': /token
[2023-05-01T13:00:56.861+0000] {connectionpool.py:813} WARNING - Retrying (Retry(total=1, connect=None, read=None, redirect=None, status=None)) after connection broken by 'NewConnectionError('<urllib3.connection.HTTPSConnection object at 0xffff9bf855d0>: Failed to establish a new connection: [Errno -2] Name or service not known')': /token
[2023-05-01T13:00:56.870+0000] {connectionpool.py:813} WARNING - Retrying (Retry(total=0, connect=None, read=None, redirect=None, status=None)) after connection broken by 'NewConnectionError('<urllib3.connection.HTTPSConnection object at 0xffff9bf85990>: Failed to establish a new connection: [Errno -2] Name or service not known')': /token
[2023-05-01T13:01:00.097+0000] {connectionpool.py:813} WARNING - Retrying (Retry(total=2, connect=None, read=None, redirect=None, status=None)) after connection broken by 'NewConnectionError('<urllib3.connection.HTTPSConnection object at 0xffff9bf8f350>: Failed to establish a new connection: [Errno -2] Name or service not known')': /token
[2023-05-01T13:01:00.103+0000] {connectionpool.py:813} WARNING - Retrying (Retry(total=1, connect=None, read=None, redirect=None, status=None)) after connection broken by 'NewConnectionError('<urllib3.connection.HTTPSConnection object at 0xffff9bf8f990>: Failed to establish a new connection: [Errno -2] Name or service not known')': /token
[2023-05-01T13:01:00.111+0000] {connectionpool.py:813} WARNING - Retrying (Retry(total=0, connect=None, read=None, redirect=None, status=None)) after connection broken by 'NewConnectionError('<urllib3.connection.HTTPSConnection object at 0xffff9bf8fe10>: Failed to establish a new connection: [Errno -2] Name or service not known')': /token
[2023-05-01T13:01:01.038+0000] {connectionpool.py:813} WARNING - Retrying (Retry(total=2, connect=None, read=None, redirect=None, status=None)) after connection broken by 'NewConnectionError('<urllib3.connection.HTTPSConnection object at 0xffff9bf9a850>: Failed to establish a new connection: [Errno -2] Name or service not known')': /token
[2023-05-01T13:01:01.045+0000] {connectionpool.py:813} WARNING - Retrying (Retry(total=1, connect=None, read=None, redirect=None, status=None)) after connection broken by 'NewConnectionError('<urllib3.connection.HTTPSConnection object at 0xffff9bf9af10>: Failed to establish a new connection: [Errno -2] Name or service not known')': /token
[2023-05-01T13:01:01.049+0000] {connectionpool.py:813} WARNING - Retrying (Retry(total=0, connect=None, read=None, redirect=None, status=None)) after connection broken by 'NewConnectionError('<urllib3.connection.HTTPSConnection object at 0xffff9bffc510>: Failed to establish a new connection: [Errno -2] Name or service not known')': /token
[2023-05-01T13:01:08.611+0000] {logging_mixin.py:137} INFO - File /opt/***/data/all_teams.csv has been uploaded to Google Cloud Storage Bucket trendba-bucket-1
[2023-05-01T13:01:08.613+0000] {python.py:177} INFO - Done. Returned value was: None
[2023-05-01T13:01:08.625+0000] {taskinstance.py:1332} INFO - Marking task as SUCCESS. dag_id=push_to_bigquery, task_id=push_csv_to_cloud_storage, execution_date=20230501T113000, start_date=20230501T130055, end_date=20230501T130108
[2023-05-01T13:01:08.657+0000] {local_task_job.py:212} INFO - Task exited with return code 0
[2023-05-01T13:01:08.675+0000] {taskinstance.py:2596} INFO - 0 downstream tasks scheduled from follow-on schedule check
