[2023-05-19T00:44:36.569+0000] {taskinstance.py:1090} INFO - Dependencies all met for dep_context=non-requeueable deps ti=<TaskInstance: cloud_storage_to_bigquery_dag.create_bq_external_table manual__2023-05-19T00:44:35.053542+00:00 [queued]>
[2023-05-19T00:44:36.575+0000] {taskinstance.py:1090} INFO - Dependencies all met for dep_context=requeueable deps ti=<TaskInstance: cloud_storage_to_bigquery_dag.create_bq_external_table manual__2023-05-19T00:44:35.053542+00:00 [queued]>
[2023-05-19T00:44:36.575+0000] {taskinstance.py:1288} INFO - 
--------------------------------------------------------------------------------
[2023-05-19T00:44:36.577+0000] {taskinstance.py:1289} INFO - Starting attempt 1 of 1
[2023-05-19T00:44:36.577+0000] {taskinstance.py:1290} INFO - 
--------------------------------------------------------------------------------
[2023-05-19T00:44:36.586+0000] {taskinstance.py:1309} INFO - Executing <Task(BigQueryCreateExternalTableOperator): create_bq_external_table> on 2023-05-19 00:44:35.053542+00:00
[2023-05-19T00:44:36.590+0000] {standard_task_runner.py:55} INFO - Started process 109 to run task
[2023-05-19T00:44:36.594+0000] {standard_task_runner.py:82} INFO - Running: ['***', 'tasks', 'run', 'cloud_storage_to_bigquery_dag', 'create_bq_external_table', 'manual__2023-05-19T00:44:35.053542+00:00', '--job-id', '4393', '--raw', '--subdir', 'DAGS_FOLDER/cloud_storage_to_bigquery_dag.py', '--cfg-path', '/tmp/tmpd9hu4snz']
[2023-05-19T00:44:36.597+0000] {standard_task_runner.py:83} INFO - Job 4393: Subtask create_bq_external_table
[2023-05-19T00:44:36.658+0000] {task_command.py:389} INFO - Running <TaskInstance: cloud_storage_to_bigquery_dag.create_bq_external_table manual__2023-05-19T00:44:35.053542+00:00 [running]> on host cbefa40f06e8
[2023-05-19T00:44:36.682+0000] {warnings.py:110} WARNING - /home/***/.local/lib/python3.7/site-packages/***/utils/context.py:205: AirflowContextDeprecationWarning: Accessing 'execution_date' from the template is deprecated and will be removed in a future version. Please use 'data_interval_start' or 'logical_date' instead.
  warnings.warn(_create_deprecation_warning(key, self._deprecation_replacements[key]))

[2023-05-19T00:44:36.714+0000] {taskinstance.py:1518} INFO - Exporting the following env vars:
AIRFLOW_CTX_DAG_OWNER=***
AIRFLOW_CTX_DAG_ID=cloud_storage_to_bigquery_dag
AIRFLOW_CTX_TASK_ID=create_bq_external_table
AIRFLOW_CTX_EXECUTION_DATE=2023-05-19T00:44:35.053542+00:00
AIRFLOW_CTX_TRY_NUMBER=1
AIRFLOW_CTX_DAG_RUN_ID=manual__2023-05-19T00:44:35.053542+00:00
[2023-05-19T00:44:36.723+0000] {base.py:73} INFO - Using connection ID 'google_cloud_default' for task execution.
[2023-05-19T00:44:37.204+0000] {taskinstance.py:1776} ERROR - Task failed with exception
Traceback (most recent call last):
  File "/home/airflow/.local/lib/python3.7/site-packages/airflow/providers/google/cloud/operators/bigquery.py", line 1629, in execute
    table_resource=self.table_resource,
  File "/home/airflow/.local/lib/python3.7/site-packages/airflow/providers/google/common/hooks/base_google.py", line 468, in inner_wrapper
    return func(self, *args, **kwargs)
  File "/home/airflow/.local/lib/python3.7/site-packages/airflow/providers/google/cloud/hooks/bigquery.py", line 407, in create_empty_table
    table=table, exists_ok=exists_ok, retry=retry
  File "/home/airflow/.local/lib/python3.7/site-packages/google/cloud/bigquery/client.py", line 755, in create_table
    timeout=timeout,
  File "/home/airflow/.local/lib/python3.7/site-packages/google/cloud/bigquery/client.py", line 782, in _call_api
    return call()
  File "/home/airflow/.local/lib/python3.7/site-packages/google/api_core/retry.py", line 288, in retry_wrapped_func
    on_error=on_error,
  File "/home/airflow/.local/lib/python3.7/site-packages/google/api_core/retry.py", line 190, in retry_target
    return target()
  File "/home/airflow/.local/lib/python3.7/site-packages/google/cloud/_http/__init__.py", line 494, in api_request
    raise exceptions.from_http_response(response)
google.api_core.exceptions.BadRequest: 400 POST https://bigquery.googleapis.com/bigquery/v2/projects/trendba/datasets/all_subreddits_daily/tables?prettyPrint=false: Error while reading table: external_table_2023-05-19, error message: The table external_table_2023-05-19 cannot be read because uris did not match any data. File: gs://trendba-bucket-1/data/reddit-nba-scrape-job/2023-05-19/*.csv
[2023-05-19T00:44:37.224+0000] {taskinstance.py:1332} INFO - Marking task as FAILED. dag_id=cloud_storage_to_bigquery_dag, task_id=create_bq_external_table, execution_date=20230519T004435, start_date=20230519T004436, end_date=20230519T004437
[2023-05-19T00:44:37.238+0000] {standard_task_runner.py:105} ERROR - Failed to execute job 4393 for task create_bq_external_table (400 POST https://bigquery.googleapis.com/bigquery/v2/projects/trendba/datasets/all_subreddits_daily/tables?prettyPrint=false: Error while reading table: external_table_2023-05-19, error message: The table external_table_2023-05-19 cannot be read because uris did not match any data. File: gs://trendba-bucket-1/data/reddit-nba-scrape-job/2023-05-19/*.csv; 109)
[2023-05-19T00:44:37.288+0000] {local_task_job.py:212} INFO - Task exited with return code 1
[2023-05-19T00:44:37.303+0000] {taskinstance.py:2596} INFO - 0 downstream tasks scheduled from follow-on schedule check
