[2023-05-02T18:02:47.094+0000] {taskinstance.py:1090} INFO - Dependencies all met for dep_context=non-requeueable deps ti=<TaskInstance: scrape_and_save_to_csv.scrape_teams_17-24 scheduled__2023-05-02T16:30:00+00:00 [queued]>
[2023-05-02T18:02:47.108+0000] {taskinstance.py:1090} INFO - Dependencies all met for dep_context=requeueable deps ti=<TaskInstance: scrape_and_save_to_csv.scrape_teams_17-24 scheduled__2023-05-02T16:30:00+00:00 [queued]>
[2023-05-02T18:02:47.110+0000] {taskinstance.py:1288} INFO - 
--------------------------------------------------------------------------------
[2023-05-02T18:02:47.111+0000] {taskinstance.py:1289} INFO - Starting attempt 1 of 1
[2023-05-02T18:02:47.112+0000] {taskinstance.py:1290} INFO - 
--------------------------------------------------------------------------------
[2023-05-02T18:02:47.133+0000] {taskinstance.py:1309} INFO - Executing <Task(PythonOperator): scrape_teams_17-24> on 2023-05-02 16:30:00+00:00
[2023-05-02T18:02:47.140+0000] {standard_task_runner.py:55} INFO - Started process 22737 to run task
[2023-05-02T18:02:47.147+0000] {standard_task_runner.py:82} INFO - Running: ['***', 'tasks', 'run', 'scrape_and_save_to_csv', 'scrape_teams_17-24', 'scheduled__2023-05-02T16:30:00+00:00', '--job-id', '2242', '--raw', '--subdir', 'DAGS_FOLDER/scrape_and_save_csv_dag.py', '--cfg-path', '/tmp/tmphkcbho3e']
[2023-05-02T18:02:47.150+0000] {standard_task_runner.py:83} INFO - Job 2242: Subtask scrape_teams_17-24
[2023-05-02T18:02:47.244+0000] {task_command.py:389} INFO - Running <TaskInstance: scrape_and_save_to_csv.scrape_teams_17-24 scheduled__2023-05-02T16:30:00+00:00 [running]> on host 5d4cd8acb346
[2023-05-02T18:02:47.317+0000] {taskinstance.py:1518} INFO - Exporting the following env vars:
AIRFLOW_CTX_DAG_OWNER=***
AIRFLOW_CTX_DAG_ID=scrape_and_save_to_csv
AIRFLOW_CTX_TASK_ID=scrape_teams_17-24
AIRFLOW_CTX_EXECUTION_DATE=2023-05-02T16:30:00+00:00
AIRFLOW_CTX_TRY_NUMBER=1
AIRFLOW_CTX_DAG_RUN_ID=scheduled__2023-05-02T16:30:00+00:00
[2023-05-02T18:02:47.335+0000] {logging_mixin.py:137} INFO - HTTPSConnectionPool(host='api.pushshift.io', port=443): Max retries exceeded with url: /reddit/search/submission/?subreddit=MkeBucks&sort=created_utc&sort_type=desc&size=500 (Caused by NewConnectionError('<urllib3.connection.HTTPSConnection object at 0xffffa0044890>: Failed to establish a new connection: [Errno -2] Name or service not known'))
[2023-05-02T18:02:47.336+0000] {helpers.py:86} ERROR - HTTPSConnectionPool(host='api.pushshift.io', port=443): Max retries exceeded with url: /reddit/search/submission/?subreddit=MkeBucks&sort=created_utc&sort_type=desc&size=500 (Caused by NewConnectionError('<urllib3.connection.HTTPSConnection object at 0xffffa0044890>: Failed to establish a new connection: [Errno -2] Name or service not known'))
[2023-05-02T18:02:47.337+0000] {helpers.py:87} ERROR - Retrying! 9 attempts before skipping!
[2023-05-02T18:02:48.345+0000] {logging_mixin.py:137} INFO - HTTPSConnectionPool(host='api.pushshift.io', port=443): Max retries exceeded with url: /reddit/search/submission/?subreddit=MkeBucks&sort=created_utc&sort_type=desc&size=500 (Caused by NewConnectionError('<urllib3.connection.HTTPSConnection object at 0xffffa0038d50>: Failed to establish a new connection: [Errno -2] Name or service not known'))
[2023-05-02T18:02:48.347+0000] {helpers.py:86} ERROR - HTTPSConnectionPool(host='api.pushshift.io', port=443): Max retries exceeded with url: /reddit/search/submission/?subreddit=MkeBucks&sort=created_utc&sort_type=desc&size=500 (Caused by NewConnectionError('<urllib3.connection.HTTPSConnection object at 0xffffa0038d50>: Failed to establish a new connection: [Errno -2] Name or service not known'))
[2023-05-02T18:02:48.348+0000] {helpers.py:87} ERROR - Retrying! 8 attempts before skipping!
[2023-05-02T18:02:49.360+0000] {logging_mixin.py:137} INFO - HTTPSConnectionPool(host='api.pushshift.io', port=443): Max retries exceeded with url: /reddit/search/submission/?subreddit=MkeBucks&sort=created_utc&sort_type=desc&size=500 (Caused by NewConnectionError('<urllib3.connection.HTTPSConnection object at 0xffffa0044890>: Failed to establish a new connection: [Errno -2] Name or service not known'))
[2023-05-02T18:02:49.367+0000] {helpers.py:86} ERROR - HTTPSConnectionPool(host='api.pushshift.io', port=443): Max retries exceeded with url: /reddit/search/submission/?subreddit=MkeBucks&sort=created_utc&sort_type=desc&size=500 (Caused by NewConnectionError('<urllib3.connection.HTTPSConnection object at 0xffffa0044890>: Failed to establish a new connection: [Errno -2] Name or service not known'))
[2023-05-02T18:02:49.368+0000] {helpers.py:87} ERROR - Retrying! 7 attempts before skipping!
[2023-05-02T18:02:50.375+0000] {logging_mixin.py:137} INFO - HTTPSConnectionPool(host='api.pushshift.io', port=443): Max retries exceeded with url: /reddit/search/submission/?subreddit=MkeBucks&sort=created_utc&sort_type=desc&size=500 (Caused by NewConnectionError('<urllib3.connection.HTTPSConnection object at 0xffffa00449d0>: Failed to establish a new connection: [Errno -2] Name or service not known'))
[2023-05-02T18:02:50.377+0000] {helpers.py:86} ERROR - HTTPSConnectionPool(host='api.pushshift.io', port=443): Max retries exceeded with url: /reddit/search/submission/?subreddit=MkeBucks&sort=created_utc&sort_type=desc&size=500 (Caused by NewConnectionError('<urllib3.connection.HTTPSConnection object at 0xffffa00449d0>: Failed to establish a new connection: [Errno -2] Name or service not known'))
[2023-05-02T18:02:50.378+0000] {helpers.py:87} ERROR - Retrying! 6 attempts before skipping!
[2023-05-02T18:02:51.385+0000] {logging_mixin.py:137} INFO - HTTPSConnectionPool(host='api.pushshift.io', port=443): Max retries exceeded with url: /reddit/search/submission/?subreddit=MkeBucks&sort=created_utc&sort_type=desc&size=500 (Caused by NewConnectionError('<urllib3.connection.HTTPSConnection object at 0xffffa0044a50>: Failed to establish a new connection: [Errno -2] Name or service not known'))
[2023-05-02T18:02:51.388+0000] {helpers.py:86} ERROR - HTTPSConnectionPool(host='api.pushshift.io', port=443): Max retries exceeded with url: /reddit/search/submission/?subreddit=MkeBucks&sort=created_utc&sort_type=desc&size=500 (Caused by NewConnectionError('<urllib3.connection.HTTPSConnection object at 0xffffa0044a50>: Failed to establish a new connection: [Errno -2] Name or service not known'))
[2023-05-02T18:02:51.389+0000] {helpers.py:87} ERROR - Retrying! 5 attempts before skipping!
[2023-05-02T18:02:52.398+0000] {logging_mixin.py:137} INFO - HTTPSConnectionPool(host='api.pushshift.io', port=443): Max retries exceeded with url: /reddit/search/submission/?subreddit=MkeBucks&sort=created_utc&sort_type=desc&size=500 (Caused by NewConnectionError('<urllib3.connection.HTTPSConnection object at 0xffffa0044790>: Failed to establish a new connection: [Errno -2] Name or service not known'))
[2023-05-02T18:02:52.400+0000] {helpers.py:86} ERROR - HTTPSConnectionPool(host='api.pushshift.io', port=443): Max retries exceeded with url: /reddit/search/submission/?subreddit=MkeBucks&sort=created_utc&sort_type=desc&size=500 (Caused by NewConnectionError('<urllib3.connection.HTTPSConnection object at 0xffffa0044790>: Failed to establish a new connection: [Errno -2] Name or service not known'))
[2023-05-02T18:02:52.401+0000] {helpers.py:87} ERROR - Retrying! 4 attempts before skipping!
[2023-05-02T18:02:53.409+0000] {logging_mixin.py:137} INFO - HTTPSConnectionPool(host='api.pushshift.io', port=443): Max retries exceeded with url: /reddit/search/submission/?subreddit=MkeBucks&sort=created_utc&sort_type=desc&size=500 (Caused by NewConnectionError('<urllib3.connection.HTTPSConnection object at 0xffffa0044cd0>: Failed to establish a new connection: [Errno -2] Name or service not known'))
[2023-05-02T18:02:53.413+0000] {helpers.py:86} ERROR - HTTPSConnectionPool(host='api.pushshift.io', port=443): Max retries exceeded with url: /reddit/search/submission/?subreddit=MkeBucks&sort=created_utc&sort_type=desc&size=500 (Caused by NewConnectionError('<urllib3.connection.HTTPSConnection object at 0xffffa0044cd0>: Failed to establish a new connection: [Errno -2] Name or service not known'))
[2023-05-02T18:02:53.416+0000] {helpers.py:87} ERROR - Retrying! 3 attempts before skipping!
[2023-05-02T18:02:54.423+0000] {logging_mixin.py:137} INFO - HTTPSConnectionPool(host='api.pushshift.io', port=443): Max retries exceeded with url: /reddit/search/submission/?subreddit=MkeBucks&sort=created_utc&sort_type=desc&size=500 (Caused by NewConnectionError('<urllib3.connection.HTTPSConnection object at 0xffffa00447d0>: Failed to establish a new connection: [Errno -2] Name or service not known'))
[2023-05-02T18:02:54.425+0000] {helpers.py:86} ERROR - HTTPSConnectionPool(host='api.pushshift.io', port=443): Max retries exceeded with url: /reddit/search/submission/?subreddit=MkeBucks&sort=created_utc&sort_type=desc&size=500 (Caused by NewConnectionError('<urllib3.connection.HTTPSConnection object at 0xffffa00447d0>: Failed to establish a new connection: [Errno -2] Name or service not known'))
[2023-05-02T18:02:54.426+0000] {helpers.py:87} ERROR - Retrying! 2 attempts before skipping!
[2023-05-02T18:02:55.440+0000] {logging_mixin.py:137} INFO - HTTPSConnectionPool(host='api.pushshift.io', port=443): Max retries exceeded with url: /reddit/search/submission/?subreddit=MkeBucks&sort=created_utc&sort_type=desc&size=500 (Caused by NewConnectionError('<urllib3.connection.HTTPSConnection object at 0xffffa0044f90>: Failed to establish a new connection: [Errno -2] Name or service not known'))
[2023-05-02T18:02:55.442+0000] {helpers.py:86} ERROR - HTTPSConnectionPool(host='api.pushshift.io', port=443): Max retries exceeded with url: /reddit/search/submission/?subreddit=MkeBucks&sort=created_utc&sort_type=desc&size=500 (Caused by NewConnectionError('<urllib3.connection.HTTPSConnection object at 0xffffa0044f90>: Failed to establish a new connection: [Errno -2] Name or service not known'))
[2023-05-02T18:02:55.444+0000] {helpers.py:87} ERROR - Retrying! 1 attempts before skipping!
[2023-05-02T18:02:59.786+0000] {warnings.py:110} WARNING - /home/***/.local/lib/python3.7/site-packages/***/utils/context.py:313: AirflowContextDeprecationWarning: Accessing 'execution_date' from the template is deprecated and will be removed in a future version. Please use 'data_interval_start' or 'logical_date' instead.
  warnings.warn(_create_deprecation_warning(k, replacements))

[2023-05-02T18:03:00.539+0000] {helpers.py:80} INFO - Milwaukee Bucks: Successfully scraped!
[2023-05-02T18:03:04.358+0000] {helpers.py:80} INFO - Minnesota Timberwolves: Successfully scraped!
[2023-05-02T18:03:08.405+0000] {helpers.py:80} INFO - New Orleans Pelicans: Successfully scraped!
[2023-05-02T18:03:12.463+0000] {helpers.py:80} INFO - New York Knicks: Successfully scraped!
[2023-05-02T18:19:54.308+0000] {helpers.py:80} INFO - Oklahoma City Thunder: Successfully scraped!
[2023-05-02T18:19:58.315+0000] {helpers.py:80} INFO - Orlando Magic: Successfully scraped!
[2023-05-02T18:20:00.669+0000] {helpers.py:80} INFO - Philadelphia 76ers: Successfully scraped!
[2023-05-02T18:20:03.747+0000] {helpers.py:80} INFO - Phoenix Suns: Successfully scraped!
[2023-05-02T18:20:03.781+0000] {helpers.py:96} INFO - Saved in /opt/***/data/output_scrape_teams_17-24.csv
[2023-05-02T18:20:03.784+0000] {python.py:177} INFO - Done. Returned value was: None
[2023-05-02T18:20:03.800+0000] {taskinstance.py:1332} INFO - Marking task as SUCCESS. dag_id=scrape_and_save_to_csv, task_id=scrape_teams_17-24, execution_date=20230502T163000, start_date=20230502T180247, end_date=20230502T182003
[2023-05-02T18:20:03.893+0000] {local_task_job.py:212} INFO - Task exited with return code 0
[2023-05-02T18:20:03.914+0000] {taskinstance.py:2596} INFO - 0 downstream tasks scheduled from follow-on schedule check
