[2023-04-29T16:24:27.566+0000] {taskinstance.py:1090} INFO - Dependencies all met for dep_context=non-requeueable deps ti=<TaskInstance: push_to_bigquery.push_csv_to_cloud_storage manual__2023-04-29T16:24:25.799643+00:00 [queued]>
[2023-04-29T16:24:27.575+0000] {taskinstance.py:1090} INFO - Dependencies all met for dep_context=requeueable deps ti=<TaskInstance: push_to_bigquery.push_csv_to_cloud_storage manual__2023-04-29T16:24:25.799643+00:00 [queued]>
[2023-04-29T16:24:27.576+0000] {taskinstance.py:1288} INFO - 
--------------------------------------------------------------------------------
[2023-04-29T16:24:27.577+0000] {taskinstance.py:1289} INFO - Starting attempt 1 of 1
[2023-04-29T16:24:27.578+0000] {taskinstance.py:1290} INFO - 
--------------------------------------------------------------------------------
[2023-04-29T16:24:27.588+0000] {taskinstance.py:1309} INFO - Executing <Task(PythonOperator): push_csv_to_cloud_storage> on 2023-04-29 16:24:25.799643+00:00
[2023-04-29T16:24:27.597+0000] {standard_task_runner.py:55} INFO - Started process 163 to run task
[2023-04-29T16:24:27.602+0000] {standard_task_runner.py:82} INFO - Running: ['***', 'tasks', 'run', 'push_to_bigquery', 'push_csv_to_cloud_storage', 'manual__2023-04-29T16:24:25.799643+00:00', '--job-id', '1771', '--raw', '--subdir', 'DAGS_FOLDER/push_to_bigquery_dag.py', '--cfg-path', '/tmp/tmpwojstdp0']
[2023-04-29T16:24:27.606+0000] {standard_task_runner.py:83} INFO - Job 1771: Subtask push_csv_to_cloud_storage
[2023-04-29T16:24:27.688+0000] {task_command.py:389} INFO - Running <TaskInstance: push_to_bigquery.push_csv_to_cloud_storage manual__2023-04-29T16:24:25.799643+00:00 [running]> on host def38439e216
[2023-04-29T16:24:27.759+0000] {taskinstance.py:1518} INFO - Exporting the following env vars:
AIRFLOW_CTX_DAG_OWNER=***
AIRFLOW_CTX_DAG_ID=push_to_bigquery
AIRFLOW_CTX_TASK_ID=push_csv_to_cloud_storage
AIRFLOW_CTX_EXECUTION_DATE=2023-04-29T16:24:25.799643+00:00
AIRFLOW_CTX_TRY_NUMBER=1
AIRFLOW_CTX_DAG_RUN_ID=manual__2023-04-29T16:24:25.799643+00:00
[2023-04-29T16:24:30.784+0000] {_metadata.py:104} WARNING - Compute Engine Metadata server unavailable on attempt 1 of 3. Reason: timed out
[2023-04-29T16:24:33.797+0000] {_metadata.py:104} WARNING - Compute Engine Metadata server unavailable on attempt 2 of 3. Reason: timed out
[2023-04-29T16:24:33.800+0000] {_metadata.py:104} WARNING - Compute Engine Metadata server unavailable on attempt 3 of 3. Reason: [Errno 111] Connection refused
[2023-04-29T16:24:33.807+0000] {_default.py:297} WARNING - Authentication failed using Compute Engine authentication due to unavailable metadata server.
[2023-04-29T16:24:33.812+0000] {taskinstance.py:1776} ERROR - Task failed with exception
Traceback (most recent call last):
  File "/home/airflow/.local/lib/python3.7/site-packages/airflow/operators/python.py", line 175, in execute
    return_value = self.execute_callable()
  File "/home/airflow/.local/lib/python3.7/site-packages/airflow/operators/python.py", line 192, in execute_callable
    return self.python_callable(*self.op_args, **self.op_kwargs)
  File "/opt/airflow/dags/helpers.py", line 28, in push_to_gcs
    storage_client = storage.Client(project=project_id)
  File "/home/airflow/.local/lib/python3.7/site-packages/google/cloud/storage/client.py", line 171, in __init__
    _http=_http,
  File "/home/airflow/.local/lib/python3.7/site-packages/google/cloud/client/__init__.py", line 322, in __init__
    self, credentials=credentials, client_options=client_options, _http=_http
  File "/home/airflow/.local/lib/python3.7/site-packages/google/cloud/client/__init__.py", line 178, in __init__
    credentials, _ = google.auth.default(scopes=scopes)
  File "/home/airflow/.local/lib/python3.7/site-packages/google/auth/_default.py", line 648, in default
    raise exceptions.DefaultCredentialsError(_CLOUD_SDK_MISSING_CREDENTIALS)
google.auth.exceptions.DefaultCredentialsError: Your default credentials were not found. To set up Application Default Credentials, see https://cloud.google.com/docs/authentication/external/set-up-adc for more information.
[2023-04-29T16:24:33.833+0000] {taskinstance.py:1332} INFO - Marking task as FAILED. dag_id=push_to_bigquery, task_id=push_csv_to_cloud_storage, execution_date=20230429T162425, start_date=20230429T162427, end_date=20230429T162433
[2023-04-29T16:24:33.845+0000] {standard_task_runner.py:105} ERROR - Failed to execute job 1771 for task push_csv_to_cloud_storage (Your default credentials were not found. To set up Application Default Credentials, see https://cloud.google.com/docs/authentication/external/set-up-adc for more information.; 163)
[2023-04-29T16:24:33.884+0000] {local_task_job.py:212} INFO - Task exited with return code 1
[2023-04-29T16:24:33.903+0000] {taskinstance.py:2596} INFO - 0 downstream tasks scheduled from follow-on schedule check
