[2023-05-01T15:48:42.900+0000] {taskinstance.py:1090} INFO - Dependencies all met for dep_context=non-requeueable deps ti=<TaskInstance: scrape_and_save_to_csv.scrape_teams_17-24 scheduled__2023-05-01T14:30:00+00:00 [queued]>
[2023-05-01T15:48:42.930+0000] {taskinstance.py:1090} INFO - Dependencies all met for dep_context=requeueable deps ti=<TaskInstance: scrape_and_save_to_csv.scrape_teams_17-24 scheduled__2023-05-01T14:30:00+00:00 [queued]>
[2023-05-01T15:48:42.934+0000] {taskinstance.py:1288} INFO - 
--------------------------------------------------------------------------------
[2023-05-01T15:48:42.935+0000] {taskinstance.py:1289} INFO - Starting attempt 1 of 1
[2023-05-01T15:48:42.937+0000] {taskinstance.py:1290} INFO - 
--------------------------------------------------------------------------------
[2023-05-01T15:48:42.970+0000] {taskinstance.py:1309} INFO - Executing <Task(PythonOperator): scrape_teams_17-24> on 2023-05-01 14:30:00+00:00
[2023-05-01T15:48:42.985+0000] {standard_task_runner.py:55} INFO - Started process 5915 to run task
[2023-05-01T15:48:42.995+0000] {standard_task_runner.py:82} INFO - Running: ['***', 'tasks', 'run', 'scrape_and_save_to_csv', 'scrape_teams_17-24', 'scheduled__2023-05-01T14:30:00+00:00', '--job-id', '2061', '--raw', '--subdir', 'DAGS_FOLDER/scrape_and_save_csv_dag.py', '--cfg-path', '/tmp/tmp964_60t3']
[2023-05-01T15:48:42.998+0000] {standard_task_runner.py:83} INFO - Job 2061: Subtask scrape_teams_17-24
[2023-05-01T15:48:43.161+0000] {task_command.py:389} INFO - Running <TaskInstance: scrape_and_save_to_csv.scrape_teams_17-24 scheduled__2023-05-01T14:30:00+00:00 [running]> on host 5d4cd8acb346
[2023-05-01T15:48:43.261+0000] {taskinstance.py:1518} INFO - Exporting the following env vars:
AIRFLOW_CTX_DAG_OWNER=***
AIRFLOW_CTX_DAG_ID=scrape_and_save_to_csv
AIRFLOW_CTX_TASK_ID=scrape_teams_17-24
AIRFLOW_CTX_EXECUTION_DATE=2023-05-01T14:30:00+00:00
AIRFLOW_CTX_TRY_NUMBER=1
AIRFLOW_CTX_DAG_RUN_ID=scheduled__2023-05-01T14:30:00+00:00
[2023-05-01T15:48:43.276+0000] {logging_mixin.py:137} INFO - HTTPSConnectionPool(host='api.pushshift.io', port=443): Max retries exceeded with url: /reddit/search/submission/?subreddit=MkeBucks&sort=created_utc&sort_type=desc&size=500 (Caused by NewConnectionError('<urllib3.connection.HTTPSConnection object at 0xffffa0044890>: Failed to establish a new connection: [Errno -2] Name or service not known'))
[2023-05-01T15:48:43.281+0000] {helpers.py:86} ERROR - HTTPSConnectionPool(host='api.pushshift.io', port=443): Max retries exceeded with url: /reddit/search/submission/?subreddit=MkeBucks&sort=created_utc&sort_type=desc&size=500 (Caused by NewConnectionError('<urllib3.connection.HTTPSConnection object at 0xffffa0044890>: Failed to establish a new connection: [Errno -2] Name or service not known'))
[2023-05-01T15:48:43.283+0000] {helpers.py:87} ERROR - Retrying! 9 attempts before skipping!
[2023-05-01T15:48:44.309+0000] {logging_mixin.py:137} INFO - HTTPSConnectionPool(host='api.pushshift.io', port=443): Max retries exceeded with url: /reddit/search/submission/?subreddit=MkeBucks&sort=created_utc&sort_type=desc&size=500 (Caused by NewConnectionError('<urllib3.connection.HTTPSConnection object at 0xffffa0038d50>: Failed to establish a new connection: [Errno -2] Name or service not known'))
[2023-05-01T15:48:44.313+0000] {helpers.py:86} ERROR - HTTPSConnectionPool(host='api.pushshift.io', port=443): Max retries exceeded with url: /reddit/search/submission/?subreddit=MkeBucks&sort=created_utc&sort_type=desc&size=500 (Caused by NewConnectionError('<urllib3.connection.HTTPSConnection object at 0xffffa0038d50>: Failed to establish a new connection: [Errno -2] Name or service not known'))
[2023-05-01T15:48:44.316+0000] {helpers.py:87} ERROR - Retrying! 8 attempts before skipping!
[2023-05-01T15:48:45.340+0000] {logging_mixin.py:137} INFO - HTTPSConnectionPool(host='api.pushshift.io', port=443): Max retries exceeded with url: /reddit/search/submission/?subreddit=MkeBucks&sort=created_utc&sort_type=desc&size=500 (Caused by NewConnectionError('<urllib3.connection.HTTPSConnection object at 0xffffa0044890>: Failed to establish a new connection: [Errno -2] Name or service not known'))
[2023-05-01T15:48:45.348+0000] {helpers.py:86} ERROR - HTTPSConnectionPool(host='api.pushshift.io', port=443): Max retries exceeded with url: /reddit/search/submission/?subreddit=MkeBucks&sort=created_utc&sort_type=desc&size=500 (Caused by NewConnectionError('<urllib3.connection.HTTPSConnection object at 0xffffa0044890>: Failed to establish a new connection: [Errno -2] Name or service not known'))
[2023-05-01T15:48:45.350+0000] {helpers.py:87} ERROR - Retrying! 7 attempts before skipping!
[2023-05-01T15:48:46.375+0000] {logging_mixin.py:137} INFO - HTTPSConnectionPool(host='api.pushshift.io', port=443): Max retries exceeded with url: /reddit/search/submission/?subreddit=MkeBucks&sort=created_utc&sort_type=desc&size=500 (Caused by NewConnectionError('<urllib3.connection.HTTPSConnection object at 0xffffa00449d0>: Failed to establish a new connection: [Errno -2] Name or service not known'))
[2023-05-01T15:48:46.376+0000] {helpers.py:86} ERROR - HTTPSConnectionPool(host='api.pushshift.io', port=443): Max retries exceeded with url: /reddit/search/submission/?subreddit=MkeBucks&sort=created_utc&sort_type=desc&size=500 (Caused by NewConnectionError('<urllib3.connection.HTTPSConnection object at 0xffffa00449d0>: Failed to establish a new connection: [Errno -2] Name or service not known'))
[2023-05-01T15:48:46.377+0000] {helpers.py:87} ERROR - Retrying! 6 attempts before skipping!
[2023-05-01T15:48:47.410+0000] {logging_mixin.py:137} INFO - HTTPSConnectionPool(host='api.pushshift.io', port=443): Max retries exceeded with url: /reddit/search/submission/?subreddit=MkeBucks&sort=created_utc&sort_type=desc&size=500 (Caused by NewConnectionError('<urllib3.connection.HTTPSConnection object at 0xffffa0044a50>: Failed to establish a new connection: [Errno -2] Name or service not known'))
[2023-05-01T15:48:47.414+0000] {helpers.py:86} ERROR - HTTPSConnectionPool(host='api.pushshift.io', port=443): Max retries exceeded with url: /reddit/search/submission/?subreddit=MkeBucks&sort=created_utc&sort_type=desc&size=500 (Caused by NewConnectionError('<urllib3.connection.HTTPSConnection object at 0xffffa0044a50>: Failed to establish a new connection: [Errno -2] Name or service not known'))
[2023-05-01T15:48:47.415+0000] {helpers.py:87} ERROR - Retrying! 5 attempts before skipping!
[2023-05-01T15:48:48.426+0000] {logging_mixin.py:137} INFO - HTTPSConnectionPool(host='api.pushshift.io', port=443): Max retries exceeded with url: /reddit/search/submission/?subreddit=MkeBucks&sort=created_utc&sort_type=desc&size=500 (Caused by NewConnectionError('<urllib3.connection.HTTPSConnection object at 0xffffa0044790>: Failed to establish a new connection: [Errno -2] Name or service not known'))
[2023-05-01T15:48:48.428+0000] {helpers.py:86} ERROR - HTTPSConnectionPool(host='api.pushshift.io', port=443): Max retries exceeded with url: /reddit/search/submission/?subreddit=MkeBucks&sort=created_utc&sort_type=desc&size=500 (Caused by NewConnectionError('<urllib3.connection.HTTPSConnection object at 0xffffa0044790>: Failed to establish a new connection: [Errno -2] Name or service not known'))
[2023-05-01T15:48:48.430+0000] {helpers.py:87} ERROR - Retrying! 4 attempts before skipping!
[2023-05-01T15:48:49.455+0000] {logging_mixin.py:137} INFO - HTTPSConnectionPool(host='api.pushshift.io', port=443): Max retries exceeded with url: /reddit/search/submission/?subreddit=MkeBucks&sort=created_utc&sort_type=desc&size=500 (Caused by NewConnectionError('<urllib3.connection.HTTPSConnection object at 0xffffa0044cd0>: Failed to establish a new connection: [Errno -2] Name or service not known'))
[2023-05-01T15:48:49.457+0000] {helpers.py:86} ERROR - HTTPSConnectionPool(host='api.pushshift.io', port=443): Max retries exceeded with url: /reddit/search/submission/?subreddit=MkeBucks&sort=created_utc&sort_type=desc&size=500 (Caused by NewConnectionError('<urllib3.connection.HTTPSConnection object at 0xffffa0044cd0>: Failed to establish a new connection: [Errno -2] Name or service not known'))
[2023-05-01T15:48:49.464+0000] {helpers.py:87} ERROR - Retrying! 3 attempts before skipping!
[2023-05-01T15:48:50.491+0000] {logging_mixin.py:137} INFO - HTTPSConnectionPool(host='api.pushshift.io', port=443): Max retries exceeded with url: /reddit/search/submission/?subreddit=MkeBucks&sort=created_utc&sort_type=desc&size=500 (Caused by NewConnectionError('<urllib3.connection.HTTPSConnection object at 0xffffa00447d0>: Failed to establish a new connection: [Errno -2] Name or service not known'))
[2023-05-01T15:48:50.496+0000] {helpers.py:86} ERROR - HTTPSConnectionPool(host='api.pushshift.io', port=443): Max retries exceeded with url: /reddit/search/submission/?subreddit=MkeBucks&sort=created_utc&sort_type=desc&size=500 (Caused by NewConnectionError('<urllib3.connection.HTTPSConnection object at 0xffffa00447d0>: Failed to establish a new connection: [Errno -2] Name or service not known'))
[2023-05-01T15:48:50.497+0000] {helpers.py:87} ERROR - Retrying! 2 attempts before skipping!
[2023-05-01T15:48:51.526+0000] {logging_mixin.py:137} INFO - HTTPSConnectionPool(host='api.pushshift.io', port=443): Max retries exceeded with url: /reddit/search/submission/?subreddit=MkeBucks&sort=created_utc&sort_type=desc&size=500 (Caused by NewConnectionError('<urllib3.connection.HTTPSConnection object at 0xffffa0044f90>: Failed to establish a new connection: [Errno -2] Name or service not known'))
[2023-05-01T15:48:51.527+0000] {helpers.py:86} ERROR - HTTPSConnectionPool(host='api.pushshift.io', port=443): Max retries exceeded with url: /reddit/search/submission/?subreddit=MkeBucks&sort=created_utc&sort_type=desc&size=500 (Caused by NewConnectionError('<urllib3.connection.HTTPSConnection object at 0xffffa0044f90>: Failed to establish a new connection: [Errno -2] Name or service not known'))
[2023-05-01T15:48:51.536+0000] {helpers.py:87} ERROR - Retrying! 1 attempts before skipping!
[2023-05-01T15:48:52.564+0000] {logging_mixin.py:137} INFO - HTTPSConnectionPool(host='api.pushshift.io', port=443): Max retries exceeded with url: /reddit/search/submission/?subreddit=MkeBucks&sort=created_utc&sort_type=desc&size=500 (Caused by NewConnectionError('<urllib3.connection.HTTPSConnection object at 0xffffa0044e50>: Failed to establish a new connection: [Errno -2] Name or service not known'))
[2023-05-01T15:48:52.566+0000] {helpers.py:86} ERROR - HTTPSConnectionPool(host='api.pushshift.io', port=443): Max retries exceeded with url: /reddit/search/submission/?subreddit=MkeBucks&sort=created_utc&sort_type=desc&size=500 (Caused by NewConnectionError('<urllib3.connection.HTTPSConnection object at 0xffffa0044e50>: Failed to establish a new connection: [Errno -2] Name or service not known'))
[2023-05-01T15:48:52.568+0000] {helpers.py:87} ERROR - Retrying! 0 attempts before skipping!
[2023-05-01T15:48:53.598+0000] {logging_mixin.py:137} INFO - HTTPSConnectionPool(host='api.pushshift.io', port=443): Max retries exceeded with url: /reddit/search/submission/?subreddit=MkeBucks&sort=created_utc&sort_type=desc&size=500 (Caused by NewConnectionError('<urllib3.connection.HTTPSConnection object at 0xffffa00446d0>: Failed to establish a new connection: [Errno -2] Name or service not known'))
[2023-05-01T15:48:53.601+0000] {helpers.py:86} ERROR - HTTPSConnectionPool(host='api.pushshift.io', port=443): Max retries exceeded with url: /reddit/search/submission/?subreddit=MkeBucks&sort=created_utc&sort_type=desc&size=500 (Caused by NewConnectionError('<urllib3.connection.HTTPSConnection object at 0xffffa00446d0>: Failed to establish a new connection: [Errno -2] Name or service not known'))
[2023-05-01T15:48:53.605+0000] {helpers.py:87} ERROR - Retrying! -1 attempts before skipping!
[2023-05-01T15:48:54.636+0000] {logging_mixin.py:137} INFO - HTTPSConnectionPool(host='api.pushshift.io', port=443): Max retries exceeded with url: /reddit/search/submission/?subreddit=timberwolves&sort=created_utc&sort_type=desc&size=500 (Caused by NewConnectionError('<urllib3.connection.HTTPSConnection object at 0xffffa0044a10>: Failed to establish a new connection: [Errno -2] Name or service not known'))
[2023-05-01T15:48:54.645+0000] {helpers.py:86} ERROR - HTTPSConnectionPool(host='api.pushshift.io', port=443): Max retries exceeded with url: /reddit/search/submission/?subreddit=timberwolves&sort=created_utc&sort_type=desc&size=500 (Caused by NewConnectionError('<urllib3.connection.HTTPSConnection object at 0xffffa0044a10>: Failed to establish a new connection: [Errno -2] Name or service not known'))
[2023-05-01T15:48:54.648+0000] {helpers.py:87} ERROR - Retrying! 9 attempts before skipping!
[2023-05-01T15:48:55.670+0000] {logging_mixin.py:137} INFO - HTTPSConnectionPool(host='api.pushshift.io', port=443): Max retries exceeded with url: /reddit/search/submission/?subreddit=timberwolves&sort=created_utc&sort_type=desc&size=500 (Caused by NewConnectionError('<urllib3.connection.HTTPSConnection object at 0xffffa0044fd0>: Failed to establish a new connection: [Errno -2] Name or service not known'))
[2023-05-01T15:48:55.677+0000] {helpers.py:86} ERROR - HTTPSConnectionPool(host='api.pushshift.io', port=443): Max retries exceeded with url: /reddit/search/submission/?subreddit=timberwolves&sort=created_utc&sort_type=desc&size=500 (Caused by NewConnectionError('<urllib3.connection.HTTPSConnection object at 0xffffa0044fd0>: Failed to establish a new connection: [Errno -2] Name or service not known'))
[2023-05-01T15:48:55.680+0000] {helpers.py:87} ERROR - Retrying! 8 attempts before skipping!
[2023-05-01T15:48:56.690+0000] {logging_mixin.py:137} INFO - HTTPSConnectionPool(host='api.pushshift.io', port=443): Max retries exceeded with url: /reddit/search/submission/?subreddit=timberwolves&sort=created_utc&sort_type=desc&size=500 (Caused by NewConnectionError('<urllib3.connection.HTTPSConnection object at 0xffffa0044850>: Failed to establish a new connection: [Errno -2] Name or service not known'))
[2023-05-01T15:48:56.691+0000] {helpers.py:86} ERROR - HTTPSConnectionPool(host='api.pushshift.io', port=443): Max retries exceeded with url: /reddit/search/submission/?subreddit=timberwolves&sort=created_utc&sort_type=desc&size=500 (Caused by NewConnectionError('<urllib3.connection.HTTPSConnection object at 0xffffa0044850>: Failed to establish a new connection: [Errno -2] Name or service not known'))
[2023-05-01T15:48:56.693+0000] {helpers.py:87} ERROR - Retrying! 7 attempts before skipping!
[2023-05-01T15:49:02.613+0000] {warnings.py:110} WARNING - /home/***/.local/lib/python3.7/site-packages/***/utils/context.py:313: AirflowContextDeprecationWarning: Accessing 'execution_date' from the template is deprecated and will be removed in a future version. Please use 'data_interval_start' or 'logical_date' instead.
  warnings.warn(_create_deprecation_warning(k, replacements))

[2023-05-01T15:49:03.892+0000] {helpers.py:80} INFO - Minnesota Timberwolves: Successfully scraped!
[2023-05-01T15:49:07.479+0000] {helpers.py:80} INFO - New Orleans Pelicans: Successfully scraped!
[2023-05-01T15:49:10.632+0000] {helpers.py:80} INFO - New York Knicks: Successfully scraped!
[2023-05-01T15:49:15.485+0000] {helpers.py:80} INFO - Oklahoma City Thunder: Successfully scraped!
[2023-05-01T15:49:19.259+0000] {helpers.py:80} INFO - Orlando Magic: Successfully scraped!
[2023-05-01T15:49:21.670+0000] {helpers.py:80} INFO - Philadelphia 76ers: Successfully scraped!
[2023-05-01T15:49:25.405+0000] {helpers.py:80} INFO - Phoenix Suns: Successfully scraped!
[2023-05-01T15:49:25.429+0000] {helpers.py:96} INFO - Saved in /opt/***/data/output_scrape_teams_17-24.csv
[2023-05-01T15:49:25.432+0000] {python.py:177} INFO - Done. Returned value was: None
[2023-05-01T15:49:25.445+0000] {taskinstance.py:1332} INFO - Marking task as SUCCESS. dag_id=scrape_and_save_to_csv, task_id=scrape_teams_17-24, execution_date=20230501T143000, start_date=20230501T154842, end_date=20230501T154925
[2023-05-01T15:49:25.508+0000] {local_task_job.py:212} INFO - Task exited with return code 0
[2023-05-01T15:49:25.531+0000] {taskinstance.py:2596} INFO - 0 downstream tasks scheduled from follow-on schedule check
