[2023-05-11T01:25:20.079+0000] {taskinstance.py:1090} INFO - Dependencies all met for dep_context=non-requeueable deps ti=<TaskInstance: scrape_and_save_to_csv.scrape_teams_9-16 scheduled__2023-05-11T00:00:00+00:00 [queued]>
[2023-05-11T01:25:20.089+0000] {taskinstance.py:1090} INFO - Dependencies all met for dep_context=requeueable deps ti=<TaskInstance: scrape_and_save_to_csv.scrape_teams_9-16 scheduled__2023-05-11T00:00:00+00:00 [queued]>
[2023-05-11T01:25:20.090+0000] {taskinstance.py:1288} INFO - 
--------------------------------------------------------------------------------
[2023-05-11T01:25:20.092+0000] {taskinstance.py:1289} INFO - Starting attempt 1 of 1
[2023-05-11T01:25:20.094+0000] {taskinstance.py:1290} INFO - 
--------------------------------------------------------------------------------
[2023-05-11T01:25:20.134+0000] {taskinstance.py:1309} INFO - Executing <Task(PythonOperator): scrape_teams_9-16> on 2023-05-11 00:00:00+00:00
[2023-05-11T01:25:20.145+0000] {standard_task_runner.py:55} INFO - Started process 28660 to run task
[2023-05-11T01:25:20.156+0000] {standard_task_runner.py:82} INFO - Running: ['***', 'tasks', 'run', 'scrape_and_save_to_csv', 'scrape_teams_9-16', 'scheduled__2023-05-11T00:00:00+00:00', '--job-id', '4223', '--raw', '--subdir', 'DAGS_FOLDER/scrape_and_push_dag.py', '--cfg-path', '/tmp/tmpt74i1vkp']
[2023-05-11T01:25:20.160+0000] {standard_task_runner.py:83} INFO - Job 4223: Subtask scrape_teams_9-16
[2023-05-11T01:25:20.250+0000] {task_command.py:389} INFO - Running <TaskInstance: scrape_and_save_to_csv.scrape_teams_9-16 scheduled__2023-05-11T00:00:00+00:00 [running]> on host f41dbfa3d325
[2023-05-11T01:25:20.293+0000] {warnings.py:110} WARNING - /home/***/.local/lib/python3.7/site-packages/***/utils/context.py:205: AirflowContextDeprecationWarning: Accessing 'execution_date' from the template is deprecated and will be removed in a future version. Please use 'data_interval_start' or 'logical_date' instead.
  warnings.warn(_create_deprecation_warning(key, self._deprecation_replacements[key]))

[2023-05-11T01:25:20.345+0000] {taskinstance.py:1518} INFO - Exporting the following env vars:
AIRFLOW_CTX_DAG_OWNER=***
AIRFLOW_CTX_DAG_ID=scrape_and_save_to_csv
AIRFLOW_CTX_TASK_ID=scrape_teams_9-16
AIRFLOW_CTX_EXECUTION_DATE=2023-05-11T00:00:00+00:00
AIRFLOW_CTX_TRY_NUMBER=1
AIRFLOW_CTX_DAG_RUN_ID=scheduled__2023-05-11T00:00:00+00:00
[2023-05-11T01:25:20.360+0000] {sessions.py:161} WARNING - Retrying due to ConnectionError(MaxRetryError("HTTPSConnectionPool(host='www.reddit.com', port=443): Max retries exceeded with url: /api/v1/access_token (Caused by NewConnectionError('<urllib3.connection.HTTPSConnection object at 0xffff947d4910>: Failed to establish a new connection: [Errno -2] Name or service not known'))")) status: GET https://oauth.reddit.com/r/DetroitPistons/comments/
[2023-05-11T01:25:22.321+0000] {sessions.py:161} WARNING - Retrying due to ConnectionError(MaxRetryError("HTTPSConnectionPool(host='www.reddit.com', port=443): Max retries exceeded with url: /api/v1/access_token (Caused by NewConnectionError('<urllib3.connection.HTTPSConnection object at 0xffff947d4e10>: Failed to establish a new connection: [Errno -2] Name or service not known'))")) status: GET https://oauth.reddit.com/r/DetroitPistons/comments/
[2023-05-11T01:25:24.732+0000] {helpers.py:100} ERROR - error with request HTTPSConnectionPool(host='www.reddit.com', port=443): Max retries exceeded with url: /api/v1/access_token (Caused by NewConnectionError('<urllib3.connection.HTTPSConnection object at 0xffff948051d0>: Failed to establish a new connection: [Errno -2] Name or service not known'))
[2023-05-11T01:25:24.733+0000] {helpers.py:101} ERROR - Retrying! 9 attempts before skipping!
[2023-05-11T01:25:25.741+0000] {sessions.py:161} WARNING - Retrying due to ConnectionError(MaxRetryError("HTTPSConnectionPool(host='www.reddit.com', port=443): Max retries exceeded with url: /api/v1/access_token (Caused by NewConnectionError('<urllib3.connection.HTTPSConnection object at 0xffff94805690>: Failed to establish a new connection: [Errno -2] Name or service not known'))")) status: GET https://oauth.reddit.com/r/DetroitPistons/comments/
[2023-05-11T01:25:27.338+0000] {sessions.py:161} WARNING - Retrying due to ConnectionError(MaxRetryError("HTTPSConnectionPool(host='www.reddit.com', port=443): Max retries exceeded with url: /api/v1/access_token (Caused by NewConnectionError('<urllib3.connection.HTTPSConnection object at 0xffff9478f2d0>: Failed to establish a new connection: [Errno -2] Name or service not known'))")) status: GET https://oauth.reddit.com/r/DetroitPistons/comments/
[2023-05-11T01:25:30.671+0000] {helpers.py:100} ERROR - error with request HTTPSConnectionPool(host='www.reddit.com', port=443): Max retries exceeded with url: /api/v1/access_token (Caused by NewConnectionError('<urllib3.connection.HTTPSConnection object at 0xffff9478f390>: Failed to establish a new connection: [Errno -2] Name or service not known'))
[2023-05-11T01:25:30.673+0000] {helpers.py:101} ERROR - Retrying! 8 attempts before skipping!
[2023-05-11T01:25:31.733+0000] {sessions.py:161} WARNING - Retrying due to ConnectionError(MaxRetryError("HTTPSConnectionPool(host='www.reddit.com', port=443): Max retries exceeded with url: /api/v1/access_token (Caused by NewConnectionError('<urllib3.connection.HTTPSConnection object at 0xffff9478f650>: Failed to establish a new connection: [Errno -2] Name or service not known'))")) status: GET https://oauth.reddit.com/r/DetroitPistons/comments/
[2023-05-11T01:25:32.511+0000] {sessions.py:161} WARNING - Retrying due to ConnectionError(MaxRetryError("HTTPSConnectionPool(host='www.reddit.com', port=443): Max retries exceeded with url: /api/v1/access_token (Caused by NewConnectionError('<urllib3.connection.HTTPSConnection object at 0xffff9479b210>: Failed to establish a new connection: [Errno -2] Name or service not known'))")) status: GET https://oauth.reddit.com/r/DetroitPistons/comments/
[2023-05-11T01:25:36.445+0000] {helpers.py:100} ERROR - error with request HTTPSConnectionPool(host='www.reddit.com', port=443): Max retries exceeded with url: /api/v1/access_token (Caused by NewConnectionError('<urllib3.connection.HTTPSConnection object at 0xffff9479b590>: Failed to establish a new connection: [Errno -2] Name or service not known'))
[2023-05-11T01:25:36.447+0000] {helpers.py:101} ERROR - Retrying! 7 attempts before skipping!
[2023-05-11T01:25:37.465+0000] {sessions.py:161} WARNING - Retrying due to ConnectionError(MaxRetryError("HTTPSConnectionPool(host='www.reddit.com', port=443): Max retries exceeded with url: /api/v1/access_token (Caused by NewConnectionError('<urllib3.connection.HTTPSConnection object at 0xffff9479b810>: Failed to establish a new connection: [Errno -2] Name or service not known'))")) status: GET https://oauth.reddit.com/r/DetroitPistons/comments/
[2023-05-11T01:25:38.343+0000] {sessions.py:161} WARNING - Retrying due to ConnectionError(MaxRetryError("HTTPSConnectionPool(host='www.reddit.com', port=443): Max retries exceeded with url: /api/v1/access_token (Caused by NewConnectionError('<urllib3.connection.HTTPSConnection object at 0xffff947a4050>: Failed to establish a new connection: [Errno -2] Name or service not known'))")) status: GET https://oauth.reddit.com/r/DetroitPistons/comments/
[2023-05-11T01:25:41.788+0000] {helpers.py:100} ERROR - error with request HTTPSConnectionPool(host='www.reddit.com', port=443): Max retries exceeded with url: /api/v1/access_token (Caused by NewConnectionError('<urllib3.connection.HTTPSConnection object at 0xffff9478f690>: Failed to establish a new connection: [Errno -2] Name or service not known'))
[2023-05-11T01:25:41.789+0000] {helpers.py:101} ERROR - Retrying! 6 attempts before skipping!
[2023-05-11T01:25:42.805+0000] {sessions.py:161} WARNING - Retrying due to ConnectionError(MaxRetryError("HTTPSConnectionPool(host='www.reddit.com', port=443): Max retries exceeded with url: /api/v1/access_token (Caused by NewConnectionError('<urllib3.connection.HTTPSConnection object at 0xffff9478fe90>: Failed to establish a new connection: [Errno -2] Name or service not known'))")) status: GET https://oauth.reddit.com/r/DetroitPistons/comments/
[2023-05-11T01:25:43.714+0000] {sessions.py:161} WARNING - Retrying due to ConnectionError(MaxRetryError("HTTPSConnectionPool(host='www.reddit.com', port=443): Max retries exceeded with url: /api/v1/access_token (Caused by NewConnectionError('<urllib3.connection.HTTPSConnection object at 0xffff9478fc10>: Failed to establish a new connection: [Errno -2] Name or service not known'))")) status: GET https://oauth.reddit.com/r/DetroitPistons/comments/
[2023-05-11T01:25:47.653+0000] {helpers.py:100} ERROR - error with request HTTPSConnectionPool(host='www.reddit.com', port=443): Max retries exceeded with url: /api/v1/access_token (Caused by NewConnectionError('<urllib3.connection.HTTPSConnection object at 0xffff94805ed0>: Failed to establish a new connection: [Errno -2] Name or service not known'))
[2023-05-11T01:25:47.656+0000] {helpers.py:101} ERROR - Retrying! 5 attempts before skipping!
[2023-05-11T02:15:04.526+0000] {sessions.py:161} WARNING - Retrying due to ConnectionError(MaxRetryError("HTTPSConnectionPool(host='www.reddit.com', port=443): Max retries exceeded with url: /api/v1/access_token (Caused by NewConnectionError('<urllib3.connection.HTTPSConnection object at 0xffff94805590>: Failed to establish a new connection: [Errno -2] Name or service not known'))")) status: GET https://oauth.reddit.com/r/DetroitPistons/comments/
[2023-05-11T02:15:05.092+0000] {sessions.py:161} WARNING - Retrying due to ConnectionError(MaxRetryError("HTTPSConnectionPool(host='www.reddit.com', port=443): Max retries exceeded with url: /api/v1/access_token (Caused by NewConnectionError('<urllib3.connection.HTTPSConnection object at 0xffff94805610>: Failed to establish a new connection: [Errno -2] Name or service not known'))")) status: GET https://oauth.reddit.com/r/DetroitPistons/comments/
[2023-05-11T02:15:08.759+0000] {helpers.py:100} ERROR - error with request HTTPSConnectionPool(host='www.reddit.com', port=443): Max retries exceeded with url: /api/v1/access_token (Caused by NewConnectionError('<urllib3.connection.HTTPSConnection object at 0xffff947a4bd0>: Failed to establish a new connection: [Errno -2] Name or service not known'))
[2023-05-11T02:15:08.801+0000] {helpers.py:101} ERROR - Retrying! 4 attempts before skipping!
[2023-05-11T02:15:09.895+0000] {sessions.py:161} WARNING - Retrying due to ConnectionError(MaxRetryError("HTTPSConnectionPool(host='www.reddit.com', port=443): Max retries exceeded with url: /api/v1/access_token (Caused by NewConnectionError('<urllib3.connection.HTTPSConnection object at 0xffff947a4bd0>: Failed to establish a new connection: [Errno -2] Name or service not known'))")) status: GET https://oauth.reddit.com/r/DetroitPistons/comments/
[2023-05-11T02:15:10.875+0000] {sessions.py:161} WARNING - Retrying due to ConnectionError(MaxRetryError("HTTPSConnectionPool(host='www.reddit.com', port=443): Max retries exceeded with url: /api/v1/access_token (Caused by NewConnectionError('<urllib3.connection.HTTPSConnection object at 0xffff947ac7d0>: Failed to establish a new connection: [Errno -2] Name or service not known'))")) status: GET https://oauth.reddit.com/r/DetroitPistons/comments/
[2023-05-11T02:15:13.475+0000] {helpers.py:100} ERROR - error with request HTTPSConnectionPool(host='www.reddit.com', port=443): Max retries exceeded with url: /api/v1/access_token (Caused by NewConnectionError('<urllib3.connection.HTTPSConnection object at 0xffff947b5050>: Failed to establish a new connection: [Errno -2] Name or service not known'))
[2023-05-11T02:15:13.481+0000] {helpers.py:101} ERROR - Retrying! 3 attempts before skipping!
[2023-05-11T02:15:14.489+0000] {sessions.py:161} WARNING - Retrying due to ConnectionError(MaxRetryError("HTTPSConnectionPool(host='www.reddit.com', port=443): Max retries exceeded with url: /api/v1/access_token (Caused by NewConnectionError('<urllib3.connection.HTTPSConnection object at 0xffff94805250>: Failed to establish a new connection: [Errno -2] Name or service not known'))")) status: GET https://oauth.reddit.com/r/DetroitPistons/comments/
[2023-05-11T02:15:14.966+0000] {sessions.py:161} WARNING - Retrying due to ConnectionError(MaxRetryError("HTTPSConnectionPool(host='www.reddit.com', port=443): Max retries exceeded with url: /api/v1/access_token (Caused by NewConnectionError('<urllib3.connection.HTTPSConnection object at 0xffff94805790>: Failed to establish a new connection: [Errno -2] Name or service not known'))")) status: GET https://oauth.reddit.com/r/DetroitPistons/comments/
[2023-05-11T02:15:17.905+0000] {helpers.py:100} ERROR - error with request HTTPSConnectionPool(host='www.reddit.com', port=443): Max retries exceeded with url: /api/v1/access_token (Caused by NewConnectionError('<urllib3.connection.HTTPSConnection object at 0xffff9478f110>: Failed to establish a new connection: [Errno -2] Name or service not known'))
[2023-05-11T02:15:17.907+0000] {helpers.py:101} ERROR - Retrying! 2 attempts before skipping!
[2023-05-11T02:15:18.919+0000] {sessions.py:161} WARNING - Retrying due to ConnectionError(MaxRetryError("HTTPSConnectionPool(host='www.reddit.com', port=443): Max retries exceeded with url: /api/v1/access_token (Caused by NewConnectionError('<urllib3.connection.HTTPSConnection object at 0xffff9478fb10>: Failed to establish a new connection: [Errno -2] Name or service not known'))")) status: GET https://oauth.reddit.com/r/DetroitPistons/comments/
[2023-05-11T02:15:20.691+0000] {sessions.py:161} WARNING - Retrying due to ConnectionError(MaxRetryError("HTTPSConnectionPool(host='www.reddit.com', port=443): Max retries exceeded with url: /api/v1/access_token (Caused by NewConnectionError('<urllib3.connection.HTTPSConnection object at 0xffff9478fe50>: Failed to establish a new connection: [Errno -2] Name or service not known'))")) status: GET https://oauth.reddit.com/r/DetroitPistons/comments/
[2023-05-11T02:15:23.698+0000] {helpers.py:100} ERROR - error with request HTTPSConnectionPool(host='www.reddit.com', port=443): Max retries exceeded with url: /api/v1/access_token (Caused by NewConnectionError('<urllib3.connection.HTTPSConnection object at 0xffff947b3110>: Failed to establish a new connection: [Errno -2] Name or service not known'))
[2023-05-11T02:15:23.699+0000] {helpers.py:101} ERROR - Retrying! 1 attempts before skipping!
[2023-05-11T02:15:24.711+0000] {sessions.py:161} WARNING - Retrying due to ConnectionError(MaxRetryError("HTTPSConnectionPool(host='www.reddit.com', port=443): Max retries exceeded with url: /api/v1/access_token (Caused by NewConnectionError('<urllib3.connection.HTTPSConnection object at 0xffff947b32d0>: Failed to establish a new connection: [Errno -2] Name or service not known'))")) status: GET https://oauth.reddit.com/r/DetroitPistons/comments/
[2023-05-11T02:15:26.260+0000] {sessions.py:161} WARNING - Retrying due to ConnectionError(MaxRetryError("HTTPSConnectionPool(host='www.reddit.com', port=443): Max retries exceeded with url: /api/v1/access_token (Caused by NewConnectionError('<urllib3.connection.HTTPSConnection object at 0xffff947b3bd0>: Failed to establish a new connection: [Errno -2] Name or service not known'))")) status: GET https://oauth.reddit.com/r/DetroitPistons/comments/
[2023-05-11T02:15:28.461+0000] {helpers.py:100} ERROR - error with request HTTPSConnectionPool(host='www.reddit.com', port=443): Max retries exceeded with url: /api/v1/access_token (Caused by NewConnectionError('<urllib3.connection.HTTPSConnection object at 0xffff947c3410>: Failed to establish a new connection: [Errno -2] Name or service not known'))
[2023-05-11T02:15:28.495+0000] {helpers.py:101} ERROR - Retrying! 0 attempts before skipping!
[2023-05-11T02:15:29.505+0000] {sessions.py:161} WARNING - Retrying due to ConnectionError(MaxRetryError("HTTPSConnectionPool(host='www.reddit.com', port=443): Max retries exceeded with url: /api/v1/access_token (Caused by NewConnectionError('<urllib3.connection.HTTPSConnection object at 0xffff9478fd10>: Failed to establish a new connection: [Errno -2] Name or service not known'))")) status: GET https://oauth.reddit.com/r/DetroitPistons/comments/
[2023-05-11T02:15:31.029+0000] {sessions.py:161} WARNING - Retrying due to ConnectionError(MaxRetryError("HTTPSConnectionPool(host='www.reddit.com', port=443): Max retries exceeded with url: /api/v1/access_token (Caused by NewConnectionError('<urllib3.connection.HTTPSConnection object at 0xffff9478f790>: Failed to establish a new connection: [Errno -2] Name or service not known'))")) status: GET https://oauth.reddit.com/r/DetroitPistons/comments/
[2023-05-11T02:15:34.055+0000] {helpers.py:100} ERROR - error with request HTTPSConnectionPool(host='www.reddit.com', port=443): Max retries exceeded with url: /api/v1/access_token (Caused by NewConnectionError('<urllib3.connection.HTTPSConnection object at 0xffff94805e90>: Failed to establish a new connection: [Errno -2] Name or service not known'))
[2023-05-11T03:04:12.798+0000] {helpers.py:101} ERROR - Retrying! -1 attempts before skipping!
[2023-05-11T03:04:13.812+0000] {sessions.py:161} WARNING - Retrying due to ConnectionError(MaxRetryError("HTTPSConnectionPool(host='www.reddit.com', port=443): Max retries exceeded with url: /api/v1/access_token (Caused by NewConnectionError('<urllib3.connection.HTTPSConnection object at 0xffff94805d10>: Failed to establish a new connection: [Errno -2] Name or service not known'))")) status: GET https://oauth.reddit.com/r/warriors/comments/
[2023-05-11T03:04:14.340+0000] {sessions.py:161} WARNING - Retrying due to ConnectionError(MaxRetryError("HTTPSConnectionPool(host='www.reddit.com', port=443): Max retries exceeded with url: /api/v1/access_token (Caused by NewConnectionError('<urllib3.connection.HTTPSConnection object at 0xffff947acc50>: Failed to establish a new connection: [Errno -2] Name or service not known'))")) status: GET https://oauth.reddit.com/r/warriors/comments/
[2023-05-11T03:04:18.164+0000] {helpers.py:100} ERROR - error with request HTTPSConnectionPool(host='www.reddit.com', port=443): Max retries exceeded with url: /api/v1/access_token (Caused by NewConnectionError('<urllib3.connection.HTTPSConnection object at 0xffff947c3190>: Failed to establish a new connection: [Errno -2] Name or service not known'))
[2023-05-11T03:04:18.170+0000] {helpers.py:101} ERROR - Retrying! 9 attempts before skipping!
[2023-05-11T03:04:19.228+0000] {sessions.py:161} WARNING - Retrying due to ConnectionError(MaxRetryError("HTTPSConnectionPool(host='www.reddit.com', port=443): Max retries exceeded with url: /api/v1/access_token (Caused by NewConnectionError('<urllib3.connection.HTTPSConnection object at 0xffff947c3310>: Failed to establish a new connection: [Errno -2] Name or service not known'))")) status: GET https://oauth.reddit.com/r/warriors/comments/
[2023-05-11T03:04:20.426+0000] {sessions.py:161} WARNING - Retrying due to ConnectionError(MaxRetryError("HTTPSConnectionPool(host='www.reddit.com', port=443): Max retries exceeded with url: /api/v1/access_token (Caused by NewConnectionError('<urllib3.connection.HTTPSConnection object at 0xffff947c70d0>: Failed to establish a new connection: [Errno -2] Name or service not known'))")) status: GET https://oauth.reddit.com/r/warriors/comments/
[2023-05-11T03:04:22.822+0000] {helpers.py:100} ERROR - error with request HTTPSConnectionPool(host='www.reddit.com', port=443): Max retries exceeded with url: /api/v1/access_token (Caused by NewConnectionError('<urllib3.connection.HTTPSConnection object at 0xffff947c7890>: Failed to establish a new connection: [Errno -2] Name or service not known'))
[2023-05-11T03:04:22.824+0000] {helpers.py:101} ERROR - Retrying! 8 attempts before skipping!
[2023-05-11T03:04:23.833+0000] {sessions.py:161} WARNING - Retrying due to ConnectionError(MaxRetryError("HTTPSConnectionPool(host='www.reddit.com', port=443): Max retries exceeded with url: /api/v1/access_token (Caused by NewConnectionError('<urllib3.connection.HTTPSConnection object at 0xffff948053d0>: Failed to establish a new connection: [Errno -2] Name or service not known'))")) status: GET https://oauth.reddit.com/r/warriors/comments/
[2023-05-11T03:04:25.498+0000] {sessions.py:161} WARNING - Retrying due to ConnectionError(MaxRetryError("HTTPSConnectionPool(host='www.reddit.com', port=443): Max retries exceeded with url: /api/v1/access_token (Caused by NewConnectionError('<urllib3.connection.HTTPSConnection object at 0xffff948052d0>: Failed to establish a new connection: [Errno -2] Name or service not known'))")) status: GET https://oauth.reddit.com/r/warriors/comments/
[2023-05-11T03:04:28.362+0000] {helpers.py:100} ERROR - error with request HTTPSConnectionPool(host='www.reddit.com', port=443): Max retries exceeded with url: /api/v1/access_token (Caused by NewConnectionError('<urllib3.connection.HTTPSConnection object at 0xffff9478f5d0>: Failed to establish a new connection: [Errno -2] Name or service not known'))
[2023-05-11T03:04:28.365+0000] {helpers.py:101} ERROR - Retrying! 7 attempts before skipping!
[2023-05-11T03:04:29.393+0000] {sessions.py:161} WARNING - Retrying due to ConnectionError(MaxRetryError("HTTPSConnectionPool(host='www.reddit.com', port=443): Max retries exceeded with url: /api/v1/access_token (Caused by NewConnectionError('<urllib3.connection.HTTPSConnection object at 0xffff9478f090>: Failed to establish a new connection: [Errno -2] Name or service not known'))")) status: GET https://oauth.reddit.com/r/warriors/comments/
[2023-05-11T03:04:30.199+0000] {sessions.py:161} WARNING - Retrying due to ConnectionError(MaxRetryError("HTTPSConnectionPool(host='www.reddit.com', port=443): Max retries exceeded with url: /api/v1/access_token (Caused by NewConnectionError('<urllib3.connection.HTTPSConnection object at 0xffff9478fd50>: Failed to establish a new connection: [Errno -2] Name or service not known'))")) status: GET https://oauth.reddit.com/r/warriors/comments/
[2023-05-11T03:04:34.185+0000] {helpers.py:100} ERROR - error with request HTTPSConnectionPool(host='www.reddit.com', port=443): Max retries exceeded with url: /api/v1/access_token (Caused by NewConnectionError('<urllib3.connection.HTTPSConnection object at 0xffff947c7590>: Failed to establish a new connection: [Errno -2] Name or service not known'))
[2023-05-11T03:04:34.186+0000] {helpers.py:101} ERROR - Retrying! 6 attempts before skipping!
[2023-05-11T03:04:35.207+0000] {sessions.py:161} WARNING - Retrying due to ConnectionError(MaxRetryError("HTTPSConnectionPool(host='www.reddit.com', port=443): Max retries exceeded with url: /api/v1/access_token (Caused by NewConnectionError('<urllib3.connection.HTTPSConnection object at 0xffff947c75d0>: Failed to establish a new connection: [Errno -2] Name or service not known'))")) status: GET https://oauth.reddit.com/r/warriors/comments/
[2023-05-11T03:04:36.060+0000] {sessions.py:161} WARNING - Retrying due to ConnectionError(MaxRetryError("HTTPSConnectionPool(host='www.reddit.com', port=443): Max retries exceeded with url: /api/v1/access_token (Caused by NewConnectionError('<urllib3.connection.HTTPSConnection object at 0xffff9474e190>: Failed to establish a new connection: [Errno -2] Name or service not known'))")) status: GET https://oauth.reddit.com/r/warriors/comments/
[2023-05-11T03:04:38.329+0000] {helpers.py:100} ERROR - error with request HTTPSConnectionPool(host='www.reddit.com', port=443): Max retries exceeded with url: /api/v1/access_token (Caused by NewConnectionError('<urllib3.connection.HTTPSConnection object at 0xffff9475a090>: Failed to establish a new connection: [Errno -2] Name or service not known'))
[2023-05-11T03:04:38.332+0000] {helpers.py:101} ERROR - Retrying! 5 attempts before skipping!
[2023-05-11T03:04:39.354+0000] {sessions.py:161} WARNING - Retrying due to ConnectionError(MaxRetryError("HTTPSConnectionPool(host='www.reddit.com', port=443): Max retries exceeded with url: /api/v1/access_token (Caused by NewConnectionError('<urllib3.connection.HTTPSConnection object at 0xffff9475a090>: Failed to establish a new connection: [Errno -2] Name or service not known'))")) status: GET https://oauth.reddit.com/r/warriors/comments/
[2023-05-11T03:04:40.944+0000] {sessions.py:161} WARNING - Retrying due to ConnectionError(MaxRetryError("HTTPSConnectionPool(host='www.reddit.com', port=443): Max retries exceeded with url: /api/v1/access_token (Caused by NewConnectionError('<urllib3.connection.HTTPSConnection object at 0xffff9474e490>: Failed to establish a new connection: [Errno -2] Name or service not known'))")) status: GET https://oauth.reddit.com/r/warriors/comments/
[2023-05-11T03:55:22.039+0000] {helpers.py:100} ERROR - error with request HTTPSConnectionPool(host='www.reddit.com', port=443): Max retries exceeded with url: /api/v1/access_token (Caused by NewConnectionError('<urllib3.connection.HTTPSConnection object at 0xffff947c7a90>: Failed to establish a new connection: [Errno -2] Name or service not known'))
[2023-05-11T03:55:22.041+0000] {helpers.py:101} ERROR - Retrying! 4 attempts before skipping!
[2023-05-11T03:55:23.048+0000] {sessions.py:161} WARNING - Retrying due to ConnectionError(MaxRetryError("HTTPSConnectionPool(host='www.reddit.com', port=443): Max retries exceeded with url: /api/v1/access_token (Caused by NewConnectionError('<urllib3.connection.HTTPSConnection object at 0xffff947c7d90>: Failed to establish a new connection: [Errno -2] Name or service not known'))")) status: GET https://oauth.reddit.com/r/warriors/comments/
[2023-05-11T03:55:23.213+0000] {sessions.py:161} WARNING - Retrying due to ConnectionError(MaxRetryError("HTTPSConnectionPool(host='www.reddit.com', port=443): Max retries exceeded with url: /api/v1/access_token (Caused by NewConnectionError('<urllib3.connection.HTTPSConnection object at 0xffff9478f690>: Failed to establish a new connection: [Errno -2] Name or service not known'))")) status: GET https://oauth.reddit.com/r/warriors/comments/
[2023-05-11T03:55:26.674+0000] {helpers.py:100} ERROR - error with request HTTPSConnectionPool(host='www.reddit.com', port=443): Max retries exceeded with url: /api/v1/access_token (Caused by NewConnectionError('<urllib3.connection.HTTPSConnection object at 0xffff9478f310>: Failed to establish a new connection: [Errno -2] Name or service not known'))
[2023-05-11T03:55:26.678+0000] {helpers.py:101} ERROR - Retrying! 3 attempts before skipping!
[2023-05-11T03:55:27.688+0000] {sessions.py:161} WARNING - Retrying due to ConnectionError(MaxRetryError("HTTPSConnectionPool(host='www.reddit.com', port=443): Max retries exceeded with url: /api/v1/access_token (Caused by NewConnectionError('<urllib3.connection.HTTPSConnection object at 0xffff9478ff50>: Failed to establish a new connection: [Errno -2] Name or service not known'))")) status: GET https://oauth.reddit.com/r/warriors/comments/
[2023-05-11T03:55:29.271+0000] {sessions.py:161} WARNING - Retrying due to ConnectionError(MaxRetryError("HTTPSConnectionPool(host='www.reddit.com', port=443): Max retries exceeded with url: /api/v1/access_token (Caused by NewConnectionError('<urllib3.connection.HTTPSConnection object at 0xffff94805d10>: Failed to establish a new connection: [Errno -2] Name or service not known'))")) status: GET https://oauth.reddit.com/r/warriors/comments/
[2023-05-11T03:55:32.785+0000] {helpers.py:100} ERROR - error with request HTTPSConnectionPool(host='www.reddit.com', port=443): Max retries exceeded with url: /api/v1/access_token (Caused by NewConnectionError('<urllib3.connection.HTTPSConnection object at 0xffff947accd0>: Failed to establish a new connection: [Errno -2] Name or service not known'))
[2023-05-11T03:55:32.786+0000] {helpers.py:101} ERROR - Retrying! 2 attempts before skipping!
[2023-05-11T03:55:33.793+0000] {sessions.py:161} WARNING - Retrying due to ConnectionError(MaxRetryError("HTTPSConnectionPool(host='www.reddit.com', port=443): Max retries exceeded with url: /api/v1/access_token (Caused by NewConnectionError('<urllib3.connection.HTTPSConnection object at 0xffff948058d0>: Failed to establish a new connection: [Errno -2] Name or service not known'))")) status: GET https://oauth.reddit.com/r/warriors/comments/
[2023-05-11T03:55:34.093+0000] {sessions.py:161} WARNING - Retrying due to ConnectionError(MaxRetryError("HTTPSConnectionPool(host='www.reddit.com', port=443): Max retries exceeded with url: /api/v1/access_token (Caused by NewConnectionError('<urllib3.connection.HTTPSConnection object at 0xffff9475a650>: Failed to establish a new connection: [Errno -2] Name or service not known'))")) status: GET https://oauth.reddit.com/r/warriors/comments/
[2023-05-11T03:55:37.291+0000] {helpers.py:100} ERROR - error with request HTTPSConnectionPool(host='www.reddit.com', port=443): Max retries exceeded with url: /api/v1/access_token (Caused by NewConnectionError('<urllib3.connection.HTTPSConnection object at 0xffff94765210>: Failed to establish a new connection: [Errno -2] Name or service not known'))
[2023-05-11T03:55:37.294+0000] {helpers.py:101} ERROR - Retrying! 1 attempts before skipping!
[2023-05-11T03:55:38.320+0000] {sessions.py:161} WARNING - Retrying due to ConnectionError(MaxRetryError("HTTPSConnectionPool(host='www.reddit.com', port=443): Max retries exceeded with url: /api/v1/access_token (Caused by NewConnectionError('<urllib3.connection.HTTPSConnection object at 0xffff9474e090>: Failed to establish a new connection: [Errno -2] Name or service not known'))")) status: GET https://oauth.reddit.com/r/warriors/comments/
[2023-05-11T03:55:38.890+0000] {sessions.py:161} WARNING - Retrying due to ConnectionError(MaxRetryError("HTTPSConnectionPool(host='www.reddit.com', port=443): Max retries exceeded with url: /api/v1/access_token (Caused by NewConnectionError('<urllib3.connection.HTTPSConnection object at 0xffff9474e710>: Failed to establish a new connection: [Errno -2] Name or service not known'))")) status: GET https://oauth.reddit.com/r/warriors/comments/
[2023-05-11T03:55:39.782+0000] {local_task_job.py:277} WARNING - State of this instance has been externally set to failed. Terminating instance.
[2023-05-11T03:55:39.788+0000] {process_utils.py:133} INFO - Sending Signals.SIGTERM to group 28660. PIDs of all processes in the group: [28660]
[2023-05-11T03:55:39.789+0000] {process_utils.py:84} INFO - Sending the signal Signals.SIGTERM to group 28660
[2023-05-11T03:55:39.790+0000] {taskinstance.py:1488} ERROR - Received SIGTERM. Terminating subprocesses.
[2023-05-11T03:55:39.791+0000] {helpers.py:100} ERROR - Task received SIGTERM signal
[2023-05-11T03:55:39.792+0000] {helpers.py:101} ERROR - Retrying! 0 attempts before skipping!
[2023-05-11T03:55:40.798+0000] {sessions.py:161} WARNING - Retrying due to ConnectionError(MaxRetryError("HTTPSConnectionPool(host='www.reddit.com', port=443): Max retries exceeded with url: /api/v1/access_token (Caused by NewConnectionError('<urllib3.connection.HTTPSConnection object at 0xffff947c75d0>: Failed to establish a new connection: [Errno -2] Name or service not known'))")) status: GET https://oauth.reddit.com/r/warriors/comments/
[2023-05-11T03:55:42.643+0000] {sessions.py:161} WARNING - Retrying due to ConnectionError(MaxRetryError("HTTPSConnectionPool(host='www.reddit.com', port=443): Max retries exceeded with url: /api/v1/access_token (Caused by NewConnectionError('<urllib3.connection.HTTPSConnection object at 0xffff947c7090>: Failed to establish a new connection: [Errno -2] Name or service not known'))")) status: GET https://oauth.reddit.com/r/warriors/comments/
[2023-05-11T03:55:45.466+0000] {helpers.py:100} ERROR - error with request HTTPSConnectionPool(host='www.reddit.com', port=443): Max retries exceeded with url: /api/v1/access_token (Caused by NewConnectionError('<urllib3.connection.HTTPSConnection object at 0xffff947c3f90>: Failed to establish a new connection: [Errno -2] Name or service not known'))
[2023-05-11T03:55:45.470+0000] {helpers.py:101} ERROR - Retrying! -1 attempts before skipping!
[2023-05-11T03:55:46.498+0000] {sessions.py:161} WARNING - Retrying due to ConnectionError(MaxRetryError("HTTPSConnectionPool(host='www.reddit.com', port=443): Max retries exceeded with url: /api/v1/access_token (Caused by NewConnectionError('<urllib3.connection.HTTPSConnection object at 0xffff947c3810>: Failed to establish a new connection: [Errno -2] Name or service not known'))")) status: GET https://oauth.reddit.com/r/rockets/comments/
[2023-05-11T03:55:48.235+0000] {sessions.py:161} WARNING - Retrying due to ConnectionError(MaxRetryError("HTTPSConnectionPool(host='www.reddit.com', port=443): Max retries exceeded with url: /api/v1/access_token (Caused by NewConnectionError('<urllib3.connection.HTTPSConnection object at 0xffff947b39d0>: Failed to establish a new connection: [Errno -2] Name or service not known'))")) status: GET https://oauth.reddit.com/r/rockets/comments/
[2023-05-11T04:34:23.534+0000] {helpers.py:95} INFO - Houston Rockets: Successfully scraped!
[2023-05-11T04:34:24.460+0000] {helpers.py:95} INFO - Indiana Pacers: Successfully scraped!
[2023-05-11T04:34:26.022+0000] {helpers.py:95} INFO - Los Angeles Clippers: Successfully scraped!
[2023-05-11T04:34:33.783+0000] {helpers.py:95} INFO - Los Angeles Lakers: Successfully scraped!
[2023-05-11T04:34:35.089+0000] {helpers.py:95} INFO - Memphis Grizzlies: Successfully scraped!
[2023-05-11T04:34:41.378+0000] {helpers.py:95} INFO - Miami Heat: Successfully scraped!
[2023-05-11T04:34:41.465+0000] {helpers.py:110} INFO - Saved in /opt/***/data/output_scrape_teams_9-16.csv
[2023-05-11T04:34:41.471+0000] {python.py:177} INFO - Done. Returned value was: None
[2023-05-11T04:34:41.549+0000] {taskinstance.py:1332} INFO - Marking task as SUCCESS. dag_id=scrape_and_save_to_csv, task_id=scrape_teams_9-16, execution_date=20230511T000000, start_date=20230511T012520, end_date=20230511T043441
[2023-05-11T04:34:41.694+0000] {process_utils.py:79} INFO - Process psutil.Process(pid=28660, status='terminated', exitcode=0, started='01:25:20') (28660) terminated with exit code 0
