[2023-05-02T18:02:47.051+0000] {taskinstance.py:1090} INFO - Dependencies all met for dep_context=non-requeueable deps ti=<TaskInstance: push_to_bigquery.push_csv_to_cloud_storage scheduled__2023-05-02T16:30:00+00:00 [queued]>
[2023-05-02T18:02:47.077+0000] {taskinstance.py:1090} INFO - Dependencies all met for dep_context=requeueable deps ti=<TaskInstance: push_to_bigquery.push_csv_to_cloud_storage scheduled__2023-05-02T16:30:00+00:00 [queued]>
[2023-05-02T18:02:47.079+0000] {taskinstance.py:1288} INFO - 
--------------------------------------------------------------------------------
[2023-05-02T18:02:47.081+0000] {taskinstance.py:1289} INFO - Starting attempt 1 of 1
[2023-05-02T18:02:47.083+0000] {taskinstance.py:1290} INFO - 
--------------------------------------------------------------------------------
[2023-05-02T18:02:47.105+0000] {taskinstance.py:1309} INFO - Executing <Task(PythonOperator): push_csv_to_cloud_storage> on 2023-05-02 16:30:00+00:00
[2023-05-02T18:02:47.114+0000] {standard_task_runner.py:55} INFO - Started process 22735 to run task
[2023-05-02T18:02:47.133+0000] {standard_task_runner.py:82} INFO - Running: ['***', 'tasks', 'run', 'push_to_bigquery', 'push_csv_to_cloud_storage', 'scheduled__2023-05-02T16:30:00+00:00', '--job-id', '2240', '--raw', '--subdir', 'DAGS_FOLDER/push_to_bigquery_dag.py', '--cfg-path', '/tmp/tmpnobw_tml']
[2023-05-02T18:02:47.136+0000] {standard_task_runner.py:83} INFO - Job 2240: Subtask push_csv_to_cloud_storage
[2023-05-02T18:02:47.243+0000] {task_command.py:389} INFO - Running <TaskInstance: push_to_bigquery.push_csv_to_cloud_storage scheduled__2023-05-02T16:30:00+00:00 [running]> on host 5d4cd8acb346
[2023-05-02T18:02:47.275+0000] {warnings.py:110} WARNING - /home/***/.local/lib/python3.7/site-packages/***/utils/context.py:205: AirflowContextDeprecationWarning: Accessing 'execution_date' from the template is deprecated and will be removed in a future version. Please use 'data_interval_start' or 'logical_date' instead.
  warnings.warn(_create_deprecation_warning(key, self._deprecation_replacements[key]))

[2023-05-02T18:02:47.319+0000] {taskinstance.py:1518} INFO - Exporting the following env vars:
AIRFLOW_CTX_DAG_OWNER=***
AIRFLOW_CTX_DAG_ID=push_to_bigquery
AIRFLOW_CTX_TASK_ID=push_csv_to_cloud_storage
AIRFLOW_CTX_EXECUTION_DATE=2023-05-02T16:30:00+00:00
AIRFLOW_CTX_TRY_NUMBER=1
AIRFLOW_CTX_DAG_RUN_ID=scheduled__2023-05-02T16:30:00+00:00
[2023-05-02T18:02:47.375+0000] {connectionpool.py:813} WARNING - Retrying (Retry(total=2, connect=None, read=None, redirect=None, status=None)) after connection broken by 'NewConnectionError('<urllib3.connection.HTTPSConnection object at 0xffff9bfbf810>: Failed to establish a new connection: [Errno -2] Name or service not known')': /token
[2023-05-02T18:02:47.380+0000] {connectionpool.py:813} WARNING - Retrying (Retry(total=1, connect=None, read=None, redirect=None, status=None)) after connection broken by 'NewConnectionError('<urllib3.connection.HTTPSConnection object at 0xffff9bfbfd10>: Failed to establish a new connection: [Errno -2] Name or service not known')': /token
[2023-05-02T18:02:47.384+0000] {connectionpool.py:813} WARNING - Retrying (Retry(total=0, connect=None, read=None, redirect=None, status=None)) after connection broken by 'NewConnectionError('<urllib3.connection.HTTPSConnection object at 0xffff9bf730d0>: Failed to establish a new connection: [Errno -2] Name or service not known')': /token
[2023-05-02T18:02:49.051+0000] {connectionpool.py:813} WARNING - Retrying (Retry(total=2, connect=None, read=None, redirect=None, status=None)) after connection broken by 'NewConnectionError('<urllib3.connection.HTTPSConnection object at 0xffff9bf73a10>: Failed to establish a new connection: [Errno -2] Name or service not known')': /token
[2023-05-02T18:02:49.059+0000] {connectionpool.py:813} WARNING - Retrying (Retry(total=1, connect=None, read=None, redirect=None, status=None)) after connection broken by 'NewConnectionError('<urllib3.connection.HTTPSConnection object at 0xffff9bf7e050>: Failed to establish a new connection: [Errno -2] Name or service not known')': /token
[2023-05-02T18:02:49.078+0000] {connectionpool.py:813} WARNING - Retrying (Retry(total=0, connect=None, read=None, redirect=None, status=None)) after connection broken by 'NewConnectionError('<urllib3.connection.HTTPSConnection object at 0xffff9bf7e410>: Failed to establish a new connection: [Errno -2] Name or service not known')': /token
[2023-05-02T18:02:50.682+0000] {connectionpool.py:813} WARNING - Retrying (Retry(total=2, connect=None, read=None, redirect=None, status=None)) after connection broken by 'NewConnectionError('<urllib3.connection.HTTPSConnection object at 0xffff9bf7ed90>: Failed to establish a new connection: [Errno -2] Name or service not known')': /token
[2023-05-02T18:02:50.695+0000] {connectionpool.py:813} WARNING - Retrying (Retry(total=1, connect=None, read=None, redirect=None, status=None)) after connection broken by 'NewConnectionError('<urllib3.connection.HTTPSConnection object at 0xffff9bf06410>: Failed to establish a new connection: [Errno -2] Name or service not known')': /token
[2023-05-02T18:02:50.702+0000] {connectionpool.py:813} WARNING - Retrying (Retry(total=0, connect=None, read=None, redirect=None, status=None)) after connection broken by 'NewConnectionError('<urllib3.connection.HTTPSConnection object at 0xffff9bf06890>: Failed to establish a new connection: [Errno -2] Name or service not known')': /token
[2023-05-02T18:02:51.257+0000] {connectionpool.py:813} WARNING - Retrying (Retry(total=2, connect=None, read=None, redirect=None, status=None)) after connection broken by 'NewConnectionError('<urllib3.connection.HTTPSConnection object at 0xffff9bf0f2d0>: Failed to establish a new connection: [Errno -2] Name or service not known')': /token
[2023-05-02T18:02:51.264+0000] {connectionpool.py:813} WARNING - Retrying (Retry(total=1, connect=None, read=None, redirect=None, status=None)) after connection broken by 'NewConnectionError('<urllib3.connection.HTTPSConnection object at 0xffff9bf0f990>: Failed to establish a new connection: [Errno -2] Name or service not known')': /token
[2023-05-02T18:02:51.270+0000] {connectionpool.py:813} WARNING - Retrying (Retry(total=0, connect=None, read=None, redirect=None, status=None)) after connection broken by 'NewConnectionError('<urllib3.connection.HTTPSConnection object at 0xffff9bf7e5d0>: Failed to establish a new connection: [Errno -2] Name or service not known')': /token
[2023-05-02T18:03:04.075+0000] {logging_mixin.py:137} INFO - File /opt/***/data/all_teams.csv has been uploaded to Google Cloud Storage Bucket trendba-bucket-1
[2023-05-02T18:03:04.086+0000] {python.py:177} INFO - Done. Returned value was: None
[2023-05-02T18:03:04.122+0000] {taskinstance.py:1332} INFO - Marking task as SUCCESS. dag_id=push_to_bigquery, task_id=push_csv_to_cloud_storage, execution_date=20230502T163000, start_date=20230502T180247, end_date=20230502T180304
[2023-05-02T18:03:04.233+0000] {local_task_job.py:212} INFO - Task exited with return code 0
[2023-05-02T18:03:04.265+0000] {taskinstance.py:2596} INFO - 0 downstream tasks scheduled from follow-on schedule check
