[2023-05-02T13:41:22.837+0000] {taskinstance.py:1090} INFO - Dependencies all met for dep_context=non-requeueable deps ti=<TaskInstance: push_to_bigquery.push_csv_to_cloud_storage scheduled__2023-05-02T12:30:00+00:00 [queued]>
[2023-05-02T13:41:22.848+0000] {taskinstance.py:1090} INFO - Dependencies all met for dep_context=requeueable deps ti=<TaskInstance: push_to_bigquery.push_csv_to_cloud_storage scheduled__2023-05-02T12:30:00+00:00 [queued]>
[2023-05-02T13:41:22.849+0000] {taskinstance.py:1288} INFO - 
--------------------------------------------------------------------------------
[2023-05-02T13:41:22.855+0000] {taskinstance.py:1289} INFO - Starting attempt 1 of 1
[2023-05-02T13:41:22.857+0000] {taskinstance.py:1290} INFO - 
--------------------------------------------------------------------------------
[2023-05-02T13:41:22.873+0000] {taskinstance.py:1309} INFO - Executing <Task(PythonOperator): push_csv_to_cloud_storage> on 2023-05-02 12:30:00+00:00
[2023-05-02T13:41:22.883+0000] {standard_task_runner.py:55} INFO - Started process 22590 to run task
[2023-05-02T13:41:22.888+0000] {standard_task_runner.py:82} INFO - Running: ['***', 'tasks', 'run', 'push_to_bigquery', 'push_csv_to_cloud_storage', 'scheduled__2023-05-02T12:30:00+00:00', '--job-id', '2221', '--raw', '--subdir', 'DAGS_FOLDER/push_to_bigquery_dag.py', '--cfg-path', '/tmp/tmpe13hlqpi']
[2023-05-02T13:41:22.892+0000] {standard_task_runner.py:83} INFO - Job 2221: Subtask push_csv_to_cloud_storage
[2023-05-02T13:41:22.985+0000] {task_command.py:389} INFO - Running <TaskInstance: push_to_bigquery.push_csv_to_cloud_storage scheduled__2023-05-02T12:30:00+00:00 [running]> on host 5d4cd8acb346
[2023-05-02T13:41:23.024+0000] {warnings.py:110} WARNING - /home/***/.local/lib/python3.7/site-packages/***/utils/context.py:205: AirflowContextDeprecationWarning: Accessing 'execution_date' from the template is deprecated and will be removed in a future version. Please use 'data_interval_start' or 'logical_date' instead.
  warnings.warn(_create_deprecation_warning(key, self._deprecation_replacements[key]))

[2023-05-02T13:41:23.078+0000] {taskinstance.py:1518} INFO - Exporting the following env vars:
AIRFLOW_CTX_DAG_OWNER=***
AIRFLOW_CTX_DAG_ID=push_to_bigquery
AIRFLOW_CTX_TASK_ID=push_csv_to_cloud_storage
AIRFLOW_CTX_EXECUTION_DATE=2023-05-02T12:30:00+00:00
AIRFLOW_CTX_TRY_NUMBER=1
AIRFLOW_CTX_DAG_RUN_ID=scheduled__2023-05-02T12:30:00+00:00
[2023-05-02T13:41:23.149+0000] {connectionpool.py:813} WARNING - Retrying (Retry(total=2, connect=None, read=None, redirect=None, status=None)) after connection broken by 'NewConnectionError('<urllib3.connection.HTTPSConnection object at 0xffff9bfcc1d0>: Failed to establish a new connection: [Errno -2] Name or service not known')': /token
[2023-05-02T13:41:23.154+0000] {connectionpool.py:813} WARNING - Retrying (Retry(total=1, connect=None, read=None, redirect=None, status=None)) after connection broken by 'NewConnectionError('<urllib3.connection.HTTPSConnection object at 0xffff9bfcc650>: Failed to establish a new connection: [Errno -2] Name or service not known')': /token
[2023-05-02T13:41:23.158+0000] {connectionpool.py:813} WARNING - Retrying (Retry(total=0, connect=None, read=None, redirect=None, status=None)) after connection broken by 'NewConnectionError('<urllib3.connection.HTTPSConnection object at 0xffff9bfcc9d0>: Failed to establish a new connection: [Errno -2] Name or service not known')': /token
[2023-05-02T13:41:23.224+0000] {connectionpool.py:813} WARNING - Retrying (Retry(total=2, connect=None, read=None, redirect=None, status=None)) after connection broken by 'NewConnectionError('<urllib3.connection.HTTPSConnection object at 0xffff9bffe350>: Failed to establish a new connection: [Errno -2] Name or service not known')': /token
[2023-05-02T13:41:23.229+0000] {connectionpool.py:813} WARNING - Retrying (Retry(total=1, connect=None, read=None, redirect=None, status=None)) after connection broken by 'NewConnectionError('<urllib3.connection.HTTPSConnection object at 0xffff9bffe950>: Failed to establish a new connection: [Errno -2] Name or service not known')': /token
[2023-05-02T13:41:23.236+0000] {connectionpool.py:813} WARNING - Retrying (Retry(total=0, connect=None, read=None, redirect=None, status=None)) after connection broken by 'NewConnectionError('<urllib3.connection.HTTPSConnection object at 0xffff9bffed10>: Failed to establish a new connection: [Errno -2] Name or service not known')': /token
[2023-05-02T13:41:23.772+0000] {connectionpool.py:813} WARNING - Retrying (Retry(total=2, connect=None, read=None, redirect=None, status=None)) after connection broken by 'NewConnectionError('<urllib3.connection.HTTPSConnection object at 0xffff9bf856d0>: Failed to establish a new connection: [Errno -2] Name or service not known')': /token
[2023-05-02T13:41:23.784+0000] {connectionpool.py:813} WARNING - Retrying (Retry(total=1, connect=None, read=None, redirect=None, status=None)) after connection broken by 'NewConnectionError('<urllib3.connection.HTTPSConnection object at 0xffff9bf85d10>: Failed to establish a new connection: [Errno -2] Name or service not known')': /token
[2023-05-02T13:41:23.793+0000] {connectionpool.py:813} WARNING - Retrying (Retry(total=0, connect=None, read=None, redirect=None, status=None)) after connection broken by 'NewConnectionError('<urllib3.connection.HTTPSConnection object at 0xffff9bf8f1d0>: Failed to establish a new connection: [Errno -2] Name or service not known')': /token
[2023-05-02T13:41:25.709+0000] {connectionpool.py:813} WARNING - Retrying (Retry(total=2, connect=None, read=None, redirect=None, status=None)) after connection broken by 'NewConnectionError('<urllib3.connection.HTTPSConnection object at 0xffff9bf8fbd0>: Failed to establish a new connection: [Errno -2] Name or service not known')': /token
[2023-05-02T13:41:25.716+0000] {connectionpool.py:813} WARNING - Retrying (Retry(total=1, connect=None, read=None, redirect=None, status=None)) after connection broken by 'NewConnectionError('<urllib3.connection.HTTPSConnection object at 0xffff9bf982d0>: Failed to establish a new connection: [Errno -2] Name or service not known')': /token
[2023-05-02T13:41:25.726+0000] {connectionpool.py:813} WARNING - Retrying (Retry(total=0, connect=None, read=None, redirect=None, status=None)) after connection broken by 'NewConnectionError('<urllib3.connection.HTTPSConnection object at 0xffff9bf85310>: Failed to establish a new connection: [Errno -2] Name or service not known')': /token
[2023-05-02T13:41:30.205+0000] {connectionpool.py:813} WARNING - Retrying (Retry(total=2, connect=None, read=None, redirect=None, status=None)) after connection broken by 'NewConnectionError('<urllib3.connection.HTTPSConnection object at 0xffff9bffedd0>: Failed to establish a new connection: [Errno -2] Name or service not known')': /token
[2023-05-02T13:41:30.219+0000] {connectionpool.py:813} WARNING - Retrying (Retry(total=1, connect=None, read=None, redirect=None, status=None)) after connection broken by 'NewConnectionError('<urllib3.connection.HTTPSConnection object at 0xffff9bffe610>: Failed to establish a new connection: [Errno -2] Name or service not known')': /token
[2023-05-02T13:41:30.237+0000] {connectionpool.py:813} WARNING - Retrying (Retry(total=0, connect=None, read=None, redirect=None, status=None)) after connection broken by 'NewConnectionError('<urllib3.connection.HTTPSConnection object at 0xffff9bf98750>: Failed to establish a new connection: [Errno -2] Name or service not known')': /token
[2023-05-02T13:41:36.275+0000] {connectionpool.py:813} WARNING - Retrying (Retry(total=2, connect=None, read=None, redirect=None, status=None)) after connection broken by 'NewConnectionError('<urllib3.connection.HTTPSConnection object at 0xffff9bfa1190>: Failed to establish a new connection: [Errno -2] Name or service not known')': /token
[2023-05-02T13:41:36.290+0000] {connectionpool.py:813} WARNING - Retrying (Retry(total=1, connect=None, read=None, redirect=None, status=None)) after connection broken by 'NewConnectionError('<urllib3.connection.HTTPSConnection object at 0xffff9bfa1850>: Failed to establish a new connection: [Errno -2] Name or service not known')': /token
[2023-05-02T13:41:36.302+0000] {connectionpool.py:813} WARNING - Retrying (Retry(total=0, connect=None, read=None, redirect=None, status=None)) after connection broken by 'NewConnectionError('<urllib3.connection.HTTPSConnection object at 0xffff9bfa1cd0>: Failed to establish a new connection: [Errno -2] Name or service not known')': /token
[2023-05-02T13:58:15.368+0000] {local_task_job.py:277} WARNING - State of this instance has been externally set to failed. Terminating instance.
[2023-05-02T13:58:15.384+0000] {process_utils.py:133} INFO - Sending Signals.SIGTERM to group 22590. PIDs of all processes in the group: [22590]
[2023-05-02T13:58:15.385+0000] {process_utils.py:84} INFO - Sending the signal Signals.SIGTERM to group 22590
[2023-05-02T13:58:15.388+0000] {taskinstance.py:1488} ERROR - Received SIGTERM. Terminating subprocesses.
[2023-05-02T13:58:15.491+0000] {process_utils.py:79} INFO - Process psutil.Process(pid=22590, status='terminated', exitcode=0, started='13:41:22') (22590) terminated with exit code 0
